Workbook

Sheet CONTROL DE LECHE
A1: FECHA | B1: PRODUCTOR | C1: HORA LLEGADA | D1: VOLUMEN LECHE [L] | E1: PRUEBA ALCOHOL | F1: PH | G1: ACIDEZ [D] | H1: TEMPERATURA [C] | I1: CELULAS SOMATICAS <400 e3/ml | J1: ANTIBIOTICOS SI/NO | K1: % GRASA >3% | L1: SNG <7% | M1: DENSIDAD [Q] | N1: %H2O <8,5% | O1: P. CONGELAMIENTO >52 | P1: PROTEINA >3% | Q1: REPETICIONES | R1: ESTADO
A2: 46030
A3: 46031
A4: 46032
A5: 46033
A6: 46034
A7: 46035 | C7: 0.46319444 | D7: 3160 | E7: SR | F7: 6.91 | G7: 18 | M7: 28.4 | N7: 5.14 | O7: 48.3 | P7: 3.22
A8: 46035 | G8: 18 | I8: 775 | J8: NO | K8: 3.2 | L8: 8.09 | M8: 28.9 | N8: 5.56 | O8: 48.1 | P8: 3.2
A9: 46035 | G9: 17 | I9: 758 | J9: NO | K9: 2.7 | L9: 8.17 | M9: 29.6 | N9: 4.61 | O9: 48.6 | P9: 3.22
A10: 46036 | C10: 0.39722222 | D10: 3200 | F10: 6.81 | G10: 118 | I10: 854 | J10: NO | K10: 4.21 | L10: 8.25 | M10: 28.6 | N10: 3.87 | O10: 49 | P10: 3.27
G11: 16 | I11: 987 | J11: NO | K11: 3.7 | L11: 7.91 | M11: 27.7 | N11: 7.61 | O11: 46.9 | P11: 3.14
G12: 18 | I12: 895 | J12: NO | K12: 3.78 | L12: 8.03 | M12: 28.1 | N12: 6.25 | O12: 47.7 | P12: 3.18
A13: 46037 | D13: 3130 | F13: 6.08 | G13: 17 | I13: 908 | J13: NO | K13: 3.79 | L13: 8.29 | M13: 29.1 | N13: 3.33 | O13: 99.3 | P13: 3.28
F14: 6.8 | G14: 18 | I14: 541 | J14: NO | K14: 3.76 | L14: 8.36 | M14: 29.5 | N14: 2.53 | O14: 49.7 | P14: 3.3
G15: 15 | I15: 800 | J15: NO | K15: 3.8 | L15: 8.3 | M15: 29.2 | N15: 3.22 | O15: 49.4 | P15: 3.28
A16: 46038 | F16: 0 | G16: 0 | H16: 0 | I16: 0 | J16: 0 | K16: 1.36 | L16: 8.15 | M16: 30.7 | N16: 5 | O16: 48.4 | P16: 3.1
F17: 0 | G17: 0 | H17: 0 | I17: 0 | J17: 0 | K17: 1.34 | L17: 8.08 | M17: 30.5 | N17: 5.93 | O17: 47.9 | P17: 3.18
F18: 0 | G18: 0 | H18: 0 | I18: 0 | J18: 0 | K18: 1.65 | L18: 8.25 | M18: 30.9 | N18: 3.66 | O18: 49.1 | P18: 3.24
F19: 0 | G19: 0 | H19: 0 | I19: 0 | J19: 0 | K19: 2.24 | L19: 8.18 | M19: 30.1 | N19: 4.5 | O19: 48.6 | P19: 3.22
A20: 46039 | F20: 6.75 | G20: 18 | H20: 1 | I20: 575 | J20: NO | K20: 3.73 | L20: 8.5 | M20: 30 | N20: 0.94 | O20: 50.6 | P20: 3.35
F21: 6 | G21: 18 | I21: 987 | J21: NO | K21: 3.89 | L21: 8.2 | M21: 20.7 | N21: 4.36 | O21: 48.7 | P21: 3.25
A22: 46042 | C22: 0.44444444 | F22: 6 | G22: 18 | I22: 529 | J22: NO | K22: 3.99 | L22: 7.98 | M22: 27.7 | N22: 6.81 | O22: 47.4 | P22: 3.17
A23: 46043 | C23: 0.39722222 | F23: 6 | G23: 18 | I23: 945 | J23: NO | K23: 4.11 | L23: 8.28 | M23: 28.8 | N23: 3.52 | O23: 49.2 | P23: 3.28
B24: DESCREMADA | F24: 6 | G24: 18 | I24: 775 | J24: NO | K24: 3.97 | L24: 8.1 | M24: 28.2 | N24: 5.48 | O24: 48.1 | P24: 3.21
A25: 46044 | C25: 0.36041667 | D25: 2710 | F25: 6.63 | G25: 18 | I25: 541 | J25: NO | K25: 3.54 | L25: 7.9 | M25: 27.8 | N25: 7.74 | O25: 46.8 | P25: 3.13
F26: 6.63 | G26: 18 | I26: 633 | J26: NO | K26: 3.68 | L26: 8.17 | M26: 28.8 | N26: 4.66 | O26: 48.6 | P26: 3.23
K27: 0.45 | L27: 8.26 | M27: 32 | N27: 3.71 | O27: 49.1 | P27: 3.23
A28: 46045 | F28: 6.8 | G28: 15 | I28: 775 | J28: NO | K28: 3.56 | L28: 8.09 | M28: 28.5 | N28: 5.56 | O28: 48.1 | P28: 3.2
K29: 2.91 | L29: 5.43 | M29: 18.6 | N29: 37.3 | O29: 30.4 | P29: 2.23
K30: 3.08 | L30: 8.06 | M30: 28.8 | N30: 5.91 | O30: 47.9 | P30: 3.19
A31: 46046
A34: 46049 | C34: 0.34027778 | D34: 2680 | F34: 6.69 | G34: 18 | I34: 891 | J34: NO | K34: 3.8 | L34: 8.12 | M34: 28.5 | N34: 5.24 | O34: 48.2 | P34: 3.22
F35: 6.6 | G35: 17 | I35: 474 | J35: NO | K35: 3.89 | L35: 8.2 | M35: 20.7 | N35: 4.36 | O35: 48.7 | P35: 3.25
A36: 46050 | C36: 0.45555556 | D36: 2590 | F36: 6.78 | G36: 16 | I36: 417 | J36: NO | K36: 3.54 | L36: 7.82 | M36: 27.5 | N36: 8.65 | O36: 46.3 | P36: 3.1
F37: 6.76 | G37: 16 | I37: 417 | J37: NO | K37: 3.95 | L37: 8.09 | M37: 28.2 | N37: 5.59 | O37: 48 | P37: 3.21
K38: 3.58 | L38: 8.19 | M38: 28.9 | N38: 4.42 | O38: 48.7 | P38: 3.24
A39: 46051 | F39: 6.8 | G39: 16 | J39: NO | K39: 8.46 | L39: 7.51 | M39: 21.9 | N39: 11.7 | O39: 44.7 | P39: 3.04
F40: 6.8 | G40: 16 | J40: NO | K40: 8.48 | L40: 7.83 | M40: 23.2 | N40: 9.36 | O40: 46 | P40: 3.16
F41: 6.7 | G41: 17 | I41: 737 | J41: NO | K41: 3.75 | L41: 7.93 | M41: 27.7 | N41: 7.38 | O41: 47 | P41: 3.15
K42: 2.89 | L42: 8.03 | M42: 28.9 | N42: 6.28 | O42: 47.7 | P42: 3.17
...

Sheet INVENTARIO DINAMICO
A1: N° | B1: NOMBRE | C1: PRESENTACION | D1: ESTADO | E1: PROVEEDOR | F1: EXPIRACION | G1: ENTRADA | H1: STOCK MINIMO | I1: CONDICION | J1: STOCK INICIAL | K1: STOCK OCUPADO | L1: STOCK RESTANTE | M1: CONDICION | Q1: STOCK RESTANTE | S1: STOC DEL DIA 03/02/2026 | U1: stock 04/02 | W1: STOCK DEL 05 | Y1: STOCK 23 | Z1: =INT(TODAY()) -> 46108 | AA1: STOCK25 | AC1: STOCK 26 | AE1: STOCK 27
A2: 1 | B2: SAZONADOR DE QUESO CHEDDAR EN POLVO | C2: BOLSA DE 25 KG | D2: SOLIDO- POLVO NARANJA | E2: ALSEC - NUTRALIM | G2: 25 | H2: KG | J2: 0.47 | K2: =SUMIFS('Registro chedar dinamico'!G:G,'Registro chedar dinamico'!A:A,$Z$1) -> 0 | L2: =+Tabla1[[#This Row],[STOCK INICIAL]]-Tabla1[[#This Row],[STOCK OCUPADO]] -> 0.47 | Q2: =J2 -> 0.47 | S2: 4.266 | U2: 3.834 | W2: 3.618 | Y2: 0.793 | AA2: -0.143 | AC2: 0.75 | AE2: 0.318
A3: 2 | B3: COLORANTE URUCUM DE ACHIOTE | C3: BIDON 20 L | D3: LIQUIDO - NARANJA | G3: 1 | H3: L | J3: 3.138 | K3: =SUMIFS('Registro chedar dinamico'!M:M,'Registro chedar dinamico'!A:A,$Z$1) -> 0 | L3: =+Tabla1[[#This Row],[STOCK INICIAL]]-Tabla1[[#This Row],[STOCK OCUPADO]] -> 3.138 | Q3: =J3 -> 3.138 | S3: 6.23 | U3: 6.23 | W3: 6.23 | Y3: 1.5 | AA3: 1.5 | AC3: 1.5 | AE3: 1.1
A4: 3 | B4: ESENCIA QUESO CHEDDAR RB 2831 | C4: FRASCO DE 1 L | D4: LIQUIDO - TRANSLUCIDO | E4: SAPORITI | G4: 1 | H4: L | J4: 4 | K4: =SUMIFS('Registro chedar dinamico'!N:N,'Registro chedar dinamico'!A:A,$Z$1) -> 0 | L4: =+Tabla1[[#This Row],[STOCK INICIAL]]-Tabla1[[#This Row],[STOCK OCUPADO]] -> 4 | Q4: =J4 -> 4 | S4: 1.68 | U4: 1.68 | W4: 1.68 | Y4: 1 | AA4: 1 | AC4: 1 | AE4: 0.95
A5: 4 | B5: ESENCIA SABOR CREMA RB 2784 | C5: FRASCO DE 1 L | D5: LIQUIDO - TRANSLUCIDO | E5: SAPORITI | G5: 1 | H5: L | I5: MAYOR A 0.5 | J5: 1 | K5: 0 | L5: =+Tabla1[[#This Row],[STOCK INICIAL]]-Tabla1[[#This Row],[STOCK OCUPADO]] -> 1 | Q5: =J5 -> 1 | S5: 1 | U5: 1 | W5: 1 | Y5: 1 | AA5: 1 | AC5: 1 | AE5: 1
A6: 5 | B6: ACIDO FOSFORICO AL 85% | C6: FRASCO DE 1 L | D6: LIQUIDO - TRANSLUCIDO | E6: AMERICANA - CBBA | G6: 5 | H6: L | I6: 0 | J6: 9 | K6: =SUMIFS('Registro chedar dinamico'!J:J,'Registro chedar dinamico'!A:A,$Z$1) -> 0 | L6: =+Tabla1[[#This Row],[STOCK INICIAL]]-Tabla1[[#This Row],[STOCK OCUPADO]] -> 9 | Q6: =J6 -> 9 | S6: 10 | U6: 9.95 | W6: 9.915 | Y6: 9.934 | AA6: 9.899 | AC6: 9.899 | AE6: 9.869
A7: 6 | B7: ACIDO LACTICO AL 80% | C7: FRASCO DE 1 KG | D7: LIQUIDO - TRANSLUCIDO | E7: AMERICANA - CBBA | G7: 5 | H7: L | I7: 0 | J7: 8 | K7: =SUMIFS('Registro chedar dinamico'!H:H,'Registro chedar dinamico'!A:A,$Z$1) -> 0 | L7: =+Tabla1[[#This Row],[STOCK INICIAL]]-Tabla1[[#This Row],[STOCK OCUPADO]] -> 8 | Q7: =J7 -> 8 | S7: 12 | U7: 11.61 | W7: 11.41 | Y7: 9.572 | AA7: 9.268 | AC7: 9.268 | AE7: 8.998
A8: 7 | B8: ACIDO CITRICO | C8: BOLSA DE 25 KG | D8: SOLIDO - TEXTURA TIPO AZUCAR | E8: z | G8: 10 | H8: KG | I8: 0 | J8: 24.169 | K8: =SUMIFS('Registro chedar dinamico'!I:I,'Registro chedar dinamico'!A:A,$Z$1) -> 0 | L8: =+Tabla1[[#This Row],[STOCK INICIAL]]-Tabla1[[#This Row],[STOCK OCUPADO]] -> 24.169 | Q8: =J8 -> 24.169 | S8: 24.18 | U8: 24.18 | W8: 24.18 | Y8: 22.83 | AA8: 22.83 | AC8: 22.83 | AE8: 22.806
A9: 8 | B9: ALCOHOL ETILICO 70% | C9: BIDON DE 10 L | D9: LIQUIDO INCOLORO | E9: SOLQUIFAR | G9: 5 | H9: L | I9: MAYOR A 5 | J9: 5.25 | K9: 0 | L9: =+Tabla1[[#This Row],[STOCK INICIAL]]-Tabla1[[#This Row],[STOCK OCUPADO]] -> 5.25 | Q9: =J9 -> 5.25 | S9: 7 | U9: 7 | W9: 7 | Y9: 4 | AA9: 4 | AC9: 4 | AE9: 4
A10: 9 | B10: BICARBONATO DE SODIO | C10: BOLSA DE 25 KG | D10: SOLIDO - POLVO BLANCO | E10: PROQUINSA | G10: 50 | H10: KG | I10: MAYOR A 5 | J10: 155.95 | K10: =SUMIFS('REGISTRO DULCE DINAMICO'!E:E,'REGISTRO DULCE DINAMICO'!A:A,$Z$1) -> 0 | L10: =+Tabla1[[#This Row],[STOCK INICIAL]]-Tabla1[[#This Row],[STOCK OCUPADO]] -> 155.95 | Q10: =J10 -> 155.95 | S10: 83.53 | U10: 83.53 | W10: 83.53 | Y10: 81.595 | AA10: 81.595 | AC10: 81.595 | AE10: 80.6
A11: 10 | B11: PERFECTAMYL GEL | C11: BOLSA DE 25 KG | D11: SOLIDO - POLVO BLANCO | E11: AVEBE ROYAL | G11: 25 | H11: KG | I11: MAYOR A 10 | J11: 28.176 | K11: =SUMIFS('REGISTRO DULCE DINAMICO'!C:C,'REGISTRO DULCE DINAMICO'!A:A,$Z$1)+SUMIFS('Registro chedar dinamico'!E:E,'Registro chedar dinamico'!A:A,$Z$1) -> 0 | L11: =+Tabla1[[#This Row],[STOCK INICIAL]]-Tabla1[[#This Row],[STOCK OCUPADO]] -> 28.176 | Q11: =J11 -> 28.176 | S11: 9.02 | U11: 6.114 | W11: 4.661 | Y11: 41.571 | AA11: 36.999 | AC11: 36.999 | AE11: 27.753
A12: 11 | B12: ALMIDON MODIFICADO | C12: BOLSA DE 25 KG | D12: SOLIDO - POLVO | E12: LORENZ | G12: 50 | H12: KG | I12: MAYOR A 10 | J12: 90.85 | K12: =SUMIFS('HILADO DINAMICO'!B:B,'HILADO DINAMICO'!A:A,$Z$1) -> 0 | L12: =+Tabla1[[#This Row],[STOCK INICIAL]]-Tabla1[[#This Row],[STOCK OCUPADO]] -> 90.85 | Q12: =IFERROR(J12-LOOKUP(2,1/('HILADO DINAMICO'!B:B<>""),'HILADO DINAMICO'!B:B),J12) -> 90.85 | S12: 90.852 | U12: 90.852 | W12: 90.852 | Y12: 86.37 | AA12: 86.37 | AC12: 86.37 | AE12: 86.37
A13: 12 | B13: SAL ICL | C13: BOLSA DE 25 KG | D13: SOLIDO - POLVO BLANCO | E13: ALT - IND BRASILENA | G13: 50 | H13: KG | I13: 0 | J13: 53.67 | K13: =SUMIFS('Registro chedar dinamico'!F:F,'Registro chedar dinamico'!A:A,$Z$1) -> 0 | L13: =+Tabla1[[#This Row],[STOCK INICIAL]]-Tabla1[[#This Row],[STOCK OCUPADO]] -> 53.67 | Q13: =J13 -> 53.67 | S13: 76.3 | U13: 74.782 | W13: 74.023 | Y13: 55.505 | AA13: 53.125 | AC13: 53.125 | AE13: 51.935
A14: 13 | B14: CLORURO DE CALCIO | C14: BOLSA DE 25 KG | D14: SOLIDO - TEXTURA TIPO AZUCAR | E14: IND. CHINA | G14: 50 | H14: KG | I14: MAYOR A 5 | J14: 358.45 | K14: =SUMIFS('CUAJADA DINAMICO'!D:D,'CUAJADA DINAMICO'!A:A,$Z$1) -> 0 | L14: =+Tabla1[[#This Row],[STOCK INICIAL]]-Tabla1[[#This Row],[STOCK OCUPADO]] -> 358.45 | Q14: =J14 -> 358.45 | S14: 486.04 | U14: 486.04 | W14: 486.04 | Y14: 479.42 | AA14: 479.42 | AC14: 479.42 | AE14: 478.54
A15: 14 | B15: GELATINA EN POLVO | C15: BOLSA DE 25 KG | D15: SOLIDO - GRANULOSO AMARILLENTO | E15: ROUSSELOT - ALICAMP | G15: 10 | H15: KG | I15: 0 | J15: 10.878 | K15: =SUMIFS('Registro chedar dinamico'!L:L,'Registro chedar dinamico'!A:A,$Z$1) -> 0 | L15: =+Tabla1[[#This Row],[STOCK INICIAL]]-Tabla1[[#This Row],[STOCK OCUPADO]] -> 10.878 | Q15: =J15 -> 10.878 | S15: 10.672 | U15: 10.382 | W15: 10.237 | Y15: 8.532 | AA15: 8.058 | AC15: 8.058 | AE15: 7.826
A16: 15 | B16: AGUA DESIONIZADA | C16: BIDON DE 10 L | D16: LIQUIDO INCOLORO | E16: TELCHI | G16: 20 | H16: L | I16: MAYOR A 10 | K16: 0 | L16: =+Tabla1[[#This Row],[STOCK INICIAL]]-Tabla1[[#This Row],[STOCK OCUPADO]] -> 0 | Q16: =J16 -> 0 | S16: 36 | U16: 36 | W16: 36 | Y16: 36 | AA16: 36 | AC16: 36 | AE16: 36
A17: 16 | B17: SUERO EN POLVO | C17: BOLSA DE 25 KG | D17: SOLIDO - POLVO AMARILLENTO | E17: SANTA MARIA - MIGUEL PERETTI | G17: 25 | H17: KG | I17: -2 | J17: 21.9 | K17: =SUMIFS('Registro chedar dinamico'!D:D,'Registro chedar dinamico'!A:A,$Z$1) -> 0 | L17: =+Tabla1[[#This Row],[STOCK INICIAL]]-Tabla1[[#This Row],[STOCK OCUPADO]] -> 21.9 | Q17: =J17 -> 21.9 | S17: 66.37 | U17: 63.464 | W17: 62.011 | Y17: 41.679 | AA17: 37.107 | AC17: 37.107 | AE17: 34.821
A18: 17 | B18: HIDROXIDO DE SODIO 0.11 N | C18: FRASCO DE 1 L | D18: LIQUIDO INCOLORO | E18: TELCHI | G18: 2 | H18: L | I18: MAYOR A 0.25 | K18: 0 | L18: =+Tabla1[[#This Row],[STOCK INICIAL]]-Tabla1[[#This Row],[STOCK OCUPADO]] -> 0 | Q18: =J18 -> 0 | S18: 0.43 | U18: 0.43 | W18: 0.43 | Y18: 0.43 | AA18: 0.43 | AC18: 0.43 | AE18: 0.43
A19: 18 | B19: AGAR AGAR | C19: BOLSA DE 1 KG | D19: SOLIDO - POLVO AMARILLENTO | E19: NUTRALIM | G19: 1 | H19: KG | I19: MAYOR A 2 | J19: 4.503 | K19: =SUMIFS('REGISTRO DULCE DINAMICO'!D:D,'REGISTRO DULCE DINAMICO'!A:A,$Z$1) -> 0 | L19: =+Tabla1[[#This Row],[STOCK INICIAL]]-Tabla1[[#This Row],[STOCK OCUPADO]] -> 4.503 | Q19: =J19 -> 4.503 | S19: 1.68 | U19: 1.68 | W19: 1.68 | Y19: 1.24 | AA19: 1.24 | AC19: 1.24 | AE19: 0.94
A20: 19 | B20: SORBATO DE POTASIO | C20: BOLSA DE 25 KG | D20: SOLIDO - TEXTURA GRANULADA | G20: 10 | H20: KG | I20: MAYOR A 0,5 | J20: =6.45+0.433 -> 6.883 | K20: =SUMIFS('Registro chedar dinamico'!K:K,'Registro chedar dinamico'!A:A,$Z$1)+SUMIFS('REGISTRO DULCE DINAMICO'!F:F,'REGISTRO DULCE DINAMICO'!A:A,$Z$1) -> 0 | L20: =+Tabla1[[#This Row],[STOCK INICIAL]]-Tabla1[[#This Row],[STOCK OCUPADO]] -> 6.883 | Q20: =J20 -> 6.883 | S20: 14.19 | U20: 14.19 | W20: 14.19 | Y20: 12 | AA20: 12 | AC20: 12 | AE20: 11.596
A21: 20 | B21: GOMA XANTANA | C21: BOLSA DE 1 KG | D21: SOLIDO - POLVO BLANCO | E21: AMERICANA - CBBA | G21: 1 | H21: KG | I21: MAYOR A 0.25 | K21: 0 | L21: =+Tabla1[[#This Row],[STOCK INICIAL]]-Tabla1[[#This Row],[STOCK OCUPADO]] -> 0 | Q21: =J21 -> 0 | S21: 0.478 | U21: 0.478 | W21: 0.478 | Y21: 0.478 | AA21: 0.478 | AC21: 0.478 | AE21: 0.478
A22: 21 | B22: VAINILLA | C22: FRASCO 1/2 L | D22: LIQUIDO | E22: BIOTAL | G22: 0.5 | H22: L | I22: MAYOR A 10 | J22: 200 | K22: =SUMIFS('REGISTRO DULCE DINAMICO'!G:G,'REGISTRO DULCE DINAMICO'!A:A,$Z$1) -> 0 | L22: =+Tabla1[[#This Row],[STOCK INICIAL]]-Tabla1[[#This Row],[STOCK OCUPADO]] -> 200 | Q22: =J22 -> 200 | S22: 0.282 | U22: 0.282 | W22: 0.282 | Y22: 0.229 | AA22: 0.229 | AC22: 0.229 | AE22: 0.217
A23: 22 | B23: EDULCORANTE LIQUIDO | C23: BALDE DE 20 KG | E23: MAPRIAL | G23: 10 | H23: KG | I23: MAYOR 15 | J23: 16 | K23: 0 | L23: =+Tabla1[[#This Row],[STOCK INICIAL]]-Tabla1[[#This Row],[STOCK OCUPADO]] -> 16 | Q23: =J23 -> 16 | S23: 12.8 | U23: 12.8 | W23: 12.8 | Y23: 6 | AA23: 6 | AC23: 6 | AE23: 6
A24: 23 | B24: HIDROXIDO DE SODIO | C24: BOLSA DE 1 KG | D24: SOLIDO - BLANCO CRISTALINO | G24: 4 | H24: KG | I24: MAYOR A 1 | K24: 0 | L24: =+Tabla1[[#This Row],[STOCK INICIAL]]-Tabla1[[#This Row],[STOCK OCUPADO]] -> 0 | Q24: =J24 -> 0 | S24: 4 | U24: 4 | W24: 4 | Y24: 4 | AA24: 4 | AC24: 4 | AE24: 4
A25: 24 | B25: SOLUCION DESINFECTANTE 15% | C25: BIDON DE 20 KG | D25: LIQUIDO | E25: SPARTAN | G25: 20 | H25: L | I25: MAYOR A 5 | K25: 0 | L25: =+Tabla1[[#This Row],[STOCK INICIAL]]-Tabla1[[#This Row],[STOCK OCUPADO]] -> 0 | Q25: =J25 -> 0 | S25: 20 | U25: 20 | W25: 20 | Y25: 20 | AA25: 20 | AC25: 20 | AE25: 20
A26: 25 | B26: CLOROCLEAN | C26: BIDON DE 20 KG | D26: LIQUIDO | E26: SPARTAN | G26: 20 | H26: L | I26: MAYOR A 5 | K26: 0 | L26: =+Tabla1[[#This Row],[STOCK INICIAL]]-Tabla1[[#This Row],[STOCK OCUPADO]] -> 0 | Q26: =J26 -> 0 | S26: 20 | U26: 20 | W26: 20 | Y26: 20 | AA26: 20 | AC26: 20 | AE26: 20
A27: 26 | B27: HIPROX 500 - PEROXIDO DE HIDROGENO | C27: BIDON DE 20 KG | D27: LIQUIDO | E27: EVONIK | G27: 20 | H27: KG | I27: MAYOR A 5 | K27: 0 | L27: =+Tabla1[[#This Row],[STOCK INICIAL]]-Tabla1[[#This Row],[STOCK OCUPADO]] -> 0 | Q27: =J27 -> 0 | S27: 20 | U27: 20 | W27: 20 | Y27: 20 | AA27: 20 | AC27: 20 | AE27: 20
A28: 23 | B28: MANTEQUILLA | C28: BIDON | G28: 20 | H28: KG | K28: =SUMIFS('Registro chedar dinamico'!B:B,'Registro chedar dinamico'!A:A,$Z$1) -> 0 | L28: =+Tabla1[[#This Row],[STOCK INICIAL]]-Tabla1[[#This Row],[STOCK OCUPADO]] -> 0 | Q28: =J28 -> 0 | S28: 40 | U28: 17.6 | W28: 7.2 | Y28: -7.6 | AA28: -41.2 | AC28: -41.2 | AE28: -58
A29: 28 | B29: AZUCAR | C29: BOLSA DE 25 KG | D29: SOLIDO | E29: AGUAI | G29: 50 | H29: KG | I29: mayor 50 | J29: 2700 | K29: =SUMIFS('REGISTRO DULCE DINAMICO'!B:B,'REGISTRO DULCE DINAMICO'!A:A,$Z$1) -> 0 | L29: =+Tabla1[[#This Row],[STOCK INICIAL]]-Tabla1[[#This Row],[STOCK OCUPADO]] -> 2700 | S29: 0 | U29: 0 | W29: 0 | Y29: 50 | AA29: 50 | AC29: 50 | AE29: 108
A30: 29 | B30: FERMENTO HANSEN | C30: BOLSA DE 0,025 KG | D30: SOLIDO | G30: 0.175 | H30: KG | I30: MAYOR | J30: 0.25 | K30: =SUMIFS('CUAJADA DINAMICO'!B:B,'CUAJADA DINAMICO'!A:A,$Z$1) -> 0 | L30: =+Tabla1[[#This Row],[STOCK INICIAL]]-Tabla1[[#This Row],[STOCK OCUPADO]] -> 0.25 | S30: 0.1 | U30: 0.05 | W30: 0 | Y30: 0.225 | AA30: 0.225 | AC30: 0.225 | AE30: 0.175
A31: 30 | B31: CUAJO ALBAMAX | C31: FRASCO DE 0,500 KG | D31: SOLIDO | E31: ALBAMAX | G31: 0.5 | H31: KG | I31: MAYOR 1 | J31: 1.242 | K31: =SUMIFS('CUAJADA DINAMICO'!C:C,'CUAJADA DINAMICO'!A:A,$Z$1) -> 0 | L31: =+Tabla1[[#This Row],[STOCK INICIAL]]-Tabla1[[#This Row],[STOCK OCUPADO]] -> 1.242 | S31: 1.395 | U31: 1.3535 | W31: 1.2775 | Y31: 0.866 | AA31: 0.866 | AC31: 0.866 | AE31: 0.776
A32: 31 | B32: CITRIC ACID ANHIDROUS | C32: BOLSA DE 1 KG | D32: SOLIDO | E32: ALBAMAX | G32: 1.5 | H32: KG | I32: MAYOR 2 | J32: 3.481 | K32: =SUMIFS('CUAJADA DINAMICO'!C:C,'CUAJADA DINAMICO'!A:A,$Z$1) -> 0 | L32: =+Tabla1[[#This Row],[STOCK INICIAL]]-Tabla1[[#This Row],[STOCK OCUPADO]] -> 3.481
A33: 32 | B33: BENZUATO DE SODIO | C33: BOLSA DE 1 KG | D33: SOLIDO | E33: ALBAMAX | G33: 2.5 | H33: KG | I33: MAYOR 3 | J33: 0.954 | K33: =SUMIFS('CUAJADA DINAMICO'!C:C,'CUAJADA DINAMICO'!A:A,$Z$1) -> 0 | L33: =+Tabla1[[#This Row],[STOCK INICIAL]]-Tabla1[[#This Row],[STOCK OCUPADO]] -> 0.954
A34: 33 | B34: CARRAGENINA | C34: BOLSA DE 500 G | G34: 1 | I34: MAYOR 1 | J34: 0.381 | K34: =SUMIFS('CUAJADA DINAMICO'!C:C,'CUAJADA DINAMICO'!A:A,$Z$1) -> 0 | L34: =+Tabla1[[#This Row],[STOCK INICIAL]]-Tabla1[[#This Row],[STOCK OCUPADO]] -> 0.381
A35: 34 | B35: LECITINA DE SOYA | C35: BOLSA DE 1 KG | G35: 1 | I35: MAYOR 1 | J35: 0.234 | K35: =SUMIFS('CUAJADA DINAMICO'!C:C,'CUAJADA DINAMICO'!A:A,$Z$1) -> 0 | L35: =+Tabla1[[#This Row],[STOCK INICIAL]]-Tabla1[[#This Row],[STOCK OCUPADO]] -> 0.234
A36: 35 | B36: LECHE EN POLVO MAFRALAC | C36: BOLSA DE 25 KG | G36: 25 | I36: MAYOR A 1 | J36: =16+1.092+25+25 -> 67.092 | K36: =SUMIFS('CUAJADA DINAMICO'!C:C,'CUAJADA DINAMICO'!A:A,$Z$1) -> 0 | L36: =+Tabla1[[#This Row],[STOCK INICIAL]]-Tabla1[[#This Row],[STOCK OCUPADO]] -> 67.092
A37: 36 | B37: GOMA GUAR | C37: BOLSA DE 1 KG | G37: 1 | I37: MAYOR A 1 | J37: 0.763 | K37: =SUMIFS('CUAJADA DINAMICO'!C:C,'CUAJADA DINAMICO'!A:A,$Z$1) -> 0 | L37: =+Tabla1[[#This Row],[STOCK INICIAL]]-Tabla1[[#This Row],[STOCK OCUPADO]] -> 0.763
A38: 37 | B38: MALTODEXTRINA EN POLVO | C38: BOLSA 1 KG | G38: 1 | I38: MAYOR A 1 | J38: 9 | K38: =SUMIFS('CUAJADA DINAMICO'!C:C,'CUAJADA DINAMICO'!A:A,$Z$1) -> 0 | L38: =+Tabla1[[#This Row],[STOCK INICIAL]]-Tabla1[[#This Row],[STOCK OCUPADO]] -> 9
A39: 38 | B39: CARBOXIMETICELULOSA SODICA EN POLVO | C39: BOLA DE 1 KG | I39: MAYOR A 1 | J39: 5.307 | K39: =SUMIFS('CUAJADA DINAMICO'!C:C,'CUAJADA DINAMICO'!A:A,$Z$1) -> 0 | L39: =+Tabla1[[#This Row],[STOCK INICIAL]]-Tabla1[[#This Row],[STOCK OCUPADO]] -> 5.307

Sheet Inventario
A1: INSUMOS GRULAC S.R.L. | B1: NAN | C1: NAN_1 | D1: NAN_2 | E1: NAN_3 | F1: NAN_4 | G1: NAN_5 | H1: NAN_6 | I1: NAN_7 | J1: NAN_8 | K1: NAN_9 | L1: NAN_10
A2: N° | B2: NOMBRE | C2: PRESENTACION | D2: ESTADO | E2: PROVEEDOR | F2: EXPIRACION | G2: ENTRADA | H2: UNIDAD | I2: CONDICION | J2: STOCK | K2: STOCK OCUPADO | L2: STOCK RESTANTE
A3: 1 | B3: SAZONADOR DE QUESO CHEDDAR EN POLVO | C3: BOLSA DE 1 KG | D3: SOLIDO- POLVO NARANJA | E3: ALSEC - NUTRALIM | F3: 46128 | G3: 1 | H3: KG | I3: 0 | J3: 0.283
A4: 2 | B4: COLORANTE URUCUM DE ACHIOTE | C4: FRASCO DE 1 L | D4: LIQUIDO - NARANJA | F4: 46174 | G4: 1 | H4: L | I4: 0 | J4: 0.13
A5: 3 | B5: ESENCIA QUESO CHEDDAR RB 2831 | C5: FRASCO DE 1 L | D5: LIQUIDO - TRANSLUCIDO | E5: SAPORITI | F5: 46296 | G5: 1 | H5: L | I5: 0 | J5: 0.9
A6: 4 | B6: ESENCIA SABOR CREMA RB 2784 | C6: FRASCO DE 1 L | D6: LIQUIDO - TRANSLUCIDO | E6: SAPORITI | F6: 46204 | G6: 1 | H6: L | I6: MAYOR A 0.5 | J6: 1
A7: 5 | B7: ACIDO FOSFORICO AL 85% | C7: FRASCO DE 1 L | D7: LIQUIDO - TRANSLUCIDO | E7: AMERICANA - CBBA | F7: 46227 | G7: 1 | H7: L | I7: 0 | J7: 0.8
A8: 6 | B8: ACIDO LACTICO AL 80% | C8: FRASCO DE 1 L | D8: LIQUIDO - TRANSLUCIDO | E8: AMERICANA - CBBA | G8: 1 | H8: L | I8: 0 | J8: 0.45
A9: 7 | B9: ACIDO CITRICO ANHIDRIDO | C9: BOLSA DE 25 KG | D9: SOLIDO - TEXTURA TIPO AZUCAR | E9: SIN EMPRESA | F9: 46795 | G9: 25 | H9: KG | I9: 0 | J9: 23
A10: 8 | B10: ALCOHOL ETILICO 70% | C10: BIDON DE 10 L | D10: LIQUIDO INCOLORO | E10: SOLQUIFAR | F10: 46935 | G10: 10 | H10: L | I10: MAYOR A 5 | J10: 8
A11: 9 | B11: BICARBONATO DE SODIO | C11: BOLSA DE 25 KG | D11: SOLIDO - POLVO BLANCO | E11: PROQUINSA | F11: 46558 | G11: 25 | H11: KG | I11: MAYOR A 5 | J11: 21
A12: 10 | B12: PERFECTAMYL GEL | C12: BOLSA DE 25 KG | D12: SOLIDO - POLVO BLANCO | E12: AVEBE ROYAL | F12: S/F | G12: 50 | H12: KG | I12: MAYOR A 10 | J12: 29
A13: 11 | B13: ALMIDON MODIFICADO | C13: BOLSA DE 25 KG | D13: SOLIDO - POLVO | E13: LORENZ | F13: 24 MESES | G13: 25 | H13: KG | I13: MAYOR A 10 | J13: 25
A14: 12 | B14: SAL ICL | C14: BOLSA DE 25 KG | D14: SOLIDO - POLVO BLANCO | E14: ALT - IND BRASILENA | F14: 46569 | G14: 50 | H14: KG | I14: 0 | J14: 45
A15: 13 | B15: CLORURO DE SODIO | C15: BOLSA DE 25 KG | D15: SOLIDO - TEXTURA TIPO AZUCAR | E15: IND. CHINA | F15: 46350 | G15: 25 | H15: KG | I15: MAYOR A 5 | J15: 24.3
A16: 14 | B16: GELATINA EN POLVO | C16: BOLSA DE 25 KG | D16: SOLIDO - GRANULOSO AMARILLENTO | E16: ROUSSELOT - ALICAMP | F16: S/F | G16: 25 | H16: KG | I16: 0 | J16: 22.4
A17: 15 | B17: AGUA DESIONIZADA | C17: BIDON DE 10 L | D17: LIQUIDO INCOLORO | E17: TELCHI | F17: 46260 | G17: 40 | H17: L | I17: MAYOR A 10 | J17: 36
A18: 16 | B18: SUERO EN POLVO | C18: BOLSA DE 25 KG | D18: SOLIDO - POLVO AMARILLENTO | E18: SANTA MARIA - MIGUEL PERETTI | F18: NO VISIBLE | G18: 25 | H18: KG | I18: -2 | J18: 18
A19: 17 | B19: HIDROXIDO DE SODIO 0.11 N | C19: FRASCO DE 1 L | D19: LIQUIDO INCOLORO | E19: TELCHI | F19: 46249 | G19: 1 | H19: L | I19: MAYOR A 0.25 | J19: 0.95
A20: 18 | B20: AGAR - AGAR | C20: BOLSA DE 1 KG | D20: SOLIDO - POLVO AMARILLENTO | E20: NUTRALIM | F20: 46406 | G20: 5 | H20: KG | I20: MAYOR A 2 | J20: 4.5
A21: 19 | B21: SABOR PARMESANO | C21: BOLSA DE 1 KG | D21: SOLIDO - POLVO BLANCO | E21: NOVALCRUZ | F21: 46215 | G21: 1 | H21: KG | I21: MAYOR A 0,5 | J21: 1
A22: 20 | B22: GOMA XANTANA | C22: BOLSA DE 1 KG | D22: SOLIDO - POLVO BLANCO | E22: AMERICANA - CBBA | F22: 46425 | G22: 1 | H22: KG | I22: MAYOR A 0.25 | J22: 0.478
A23: 21 | B23: GRASA DE PALMA | C23: BOLSA EN CAJA DE 24 KG | D23: SOLIDO - BLANCO MANTECOSO | E23: AGROPALMA | F23: 46204 | G23: 72 | H23: KG | I23: MAYOR A 10 | J23: 72
A24: 22 | B24: ACEITE COMESTIBLE | C24: BOLSA EN CAJA DE 20 KG | D24: SOLIDO- BLANCO MANTECOSO | E24: FINCA DELAZO | F24: S/F | G24: 20 | H24: KG | I24: MAYOR A 5 | J24: 20
A25: 23 | B25: HIDROXIDO DE SODIO | C25: BOLSA DE 1 KG | D25: SOLIDO - BLANCO CRISTALINO | G25: 4 | H25: KG | I25: MAYOR A 1 | J25: 4
A26: 24 | B26: SOLUCION DESINFECTANTE 15% | C26: BIDON DE 20 KG | D26: LIQUIDO | E26: SPARTAN | F26: 46204 | G26: 20 | H26: KG | I26: MAYOR A 5 | J26: 20
A27: 25 | B27: CLOROCLEAN | C27: BIDON DE 20 KG | D27: LIQUIDO | E27: SPARTAN | F27: 46225 | G27: 20 | H27: KG | I27: MAYOR A 5 | J27: 20
A28: 26 | B28: HIPROX 500 - PEROXIDO DE HIDROGENO | C28: BIDON DE 20 KG | D28: LIQUIDO | E28: EVONIK | F28: 46157 | G28: 20 | H28: KG | I28: MAYOR A 5 | J28: 20

Sheet Recetas
B2: RECETA CHEDDAR FINAL
B3: Ingrediente | C3: Porcentaje | D3: 52 Kilos | E3: 50 Kilos | F3: 104 Kilos
B4: Cuajada | C4: 0.5097 | D4: =52*C4 -> 26.5044 | E4: =50*C4 -> 25.485 | F4: =C4*104 -> 53.0088
B5: Mantequilla | C5: 0.2234 | D5: =52*C5 -> 11.6168 | E5: =50*C5 -> 11.17 | F5: =C5*104 -> 23.2336
B6: Agua | C6: 0.15399 | D6: =52*C6 -> 8.00748 | E6: =50*C6 -> 7.6995 | F6: =C6*104 -> 16.01496
B7: Suero | C7: 0.02794 | D7: =52*C7 -> 1.45288 | E7: =50*C7 -> 1.397 | F7: =C7*104 -> 2.90576
B8: Sal ICL | C8: 0.01459 | D8: =52*C8 -> 0.75868 | E8: =50*C8 -> 0.7295 | F8: =C8*104 -> 1.51736
B9: Almidon | C9: 0.02794 | D9: =52*C9 -> 1.45288 | E9: =50*C9 -> 1.397 | F9: =C9*104 -> 2.90576
B10: Saborizante | C10: 0.00838 | D10: =52*C10 -> 0.43576 | E10: =50*C10 -> 0.419 | F10: =C10*104 -> 0.87152
B11: A. Lactico | C11: 0.01954 | D11: =52*C11 -> 1.01608 | E11: =50*C11 -> 0.977 | F11: =C11*104 -> 2.03216
B12: A. Citrico | C12: 0.00279 | D12: =52*C12 -> 0.14508 | E12: =50*C12 -> 0.1395 | F12: =C12*104 -> 0.29016
B13: A. Fosforico | C13: 0.00418 | D13: =52*C13 -> 0.21736 | E13: =50*C13 -> 0.209 | F13: =C13*104 -> 0.43472
B14: Sorbato | C14: 0.00127 | D14: =52*C14 -> 0.06604 | E14: =50*C14 -> 0.0635 | F14: =C14*104 -> 0.13208
B15: Gelatina | C15: 0.00279 | D15: =52*C15 -> 0.14508 | E15: =50*C15 -> 0.1395 | F15: =C15*104 -> 0.29016
... B17: Esencia | C17: 0.0014 | D17: =52*C17 -> 0.0728 | E17: =50*C17 -> 0.07 | F17: =C17*104 -> 0.1456
B19: Total | C19: =SUM(C4:C18) -> 1.0035 | D19: =SUM(D4:D18) -> 52.182 | E19: =SUM(E4:E18) -> 50.175 | F19: =SUM(F4:F17) -> 104.364

Sheet RECETA DE DULCE
A2: RECETA DULCE REPOSTERO
A3: Ingrediente | B3: Proporcion | C3: 220 litros | D3: 240 litros | E3: Porcentaje (%)
A4: LECHE | C4: 220 | D4: 240 | E4: =(C4/$C$11)*100 -> 100
A5: BICARBONATO DE SODIO | B5: 1,50 g/litro | C5: 0.33 | D5: 0.36 | E5: =(C5/C11)*100 -> 0.15
A6: AZUCAR | B6: 0.21 | C6: 46.2 | D6: 50.4 | E6: =(C6/C11)*100 -> 21
A7: SORBATO | B7: 0,30 g/litro | C7: 0.066 | D7: 0.072 | E7: =(C7/C11)*100 -> 0.03
A8: ALMIDON PERFECTAMYL | B8: 16 g/litro | C8: 3.52 | D8: 3.84 | E8: =(C8/C11)*100 -> 1.6
A9: VAINILLA | B9: 0,025 g/litro | C9: 0.0055 | D9: 0.006 | E9: =(C9/C11)*100 -> 0.0025
A10: AGAR - AGAR | B10: 0,535 g/litro | C10: 0.17655 | D10: 0.1926 | E10: =(C10/C11)*100 -> 0.08025
A11: TOTAL | C11: 220
A13: RECETA DULCE FAMILIAR
A14: Ingrediente | B14: Proporcion | C14: 220 litros | D14: 240 litros | E14: Porcentaje (%)
A15: BICARBONATO DE SODIO | B15: 1,16 g/litro | C15: 0.2552 | D15: 0.28 | E15: =(D15/240)*100 -> 0.11666667
A16: AZUCAR | B16: 0.18 | C16: 39.6 | D16: 43.2 | E16: =(D16/240)*100 -> 18
A17: SORBATO | B17: 0,30 g/litro | C17: 0.066 | D17: 0.072 | E17: =(D17/240)*100 -> 0.03
A18: ALMIDON PERFECTAMYL | B18: 8 g/litro | C18: 1.76 | D18: 1.92 | E18: =(D18/240)*100 -> 0.8
A19: VAINILLA | B19: 0,025 g/litro | C19: 0.0055 | D19: 0.006 | E19: =(D19/240)*100 -> 0.0025
A20: GLUCOSA | B20: 0.02 | C20: 4.4 | D20: 4.8 | E20: =(D20/240)*100 -> 2
A21: TOTAL

Sheet Registro Dulce
B5: Fecha | C5: Tipo | D5: Registro | E5: Recepcion | G5: Materia Prima y Aditivos (kg) | N5: Control 1° | R5: Control 2° | V5: Control 3° | Z5: Control 4° | AD5: Control 5° | AH5: Control 6° | AL5: Control 7° (ENVASADO) | AP5: Producto Obtenido (Kg) | AQ5: Rendimiento | AR5: Presentacion | AU5: Hora
E6: pH | F6: Acidez (D°) | G6: LECHE | H6: AZUCAR | I6: ALMIDON PERFECTAMYL | J6: AGAR -AGAR | K6: BICARBONATO DE SODIO | L6: SORBATO | M6: VAINILLA | N6: Hora | O6: Grados Bx° | P6: P. General | Q6: P. Entrada | R6: Hora | S6: Grados Bx° | T6: P. General | U6: P. Entrada | V6: Hora | W6: Grados Bx° | X6: P. General | Y6: P. Entrada | Z6: Hora | AA6: Grados Bx° | AB6: P. General | AC6: P. Entrada | AD6: Hora | AE6: Grados Bx° | AF6: P. General | AG6: P. Entrada | AH6: Hora | AI6: Grados Bx° | AJ6: P. General | AK6: P. Entrada | AL6: Hora | AM6: Grados Bx° | AN6: P. General | AO6: P. Entrada | AR6: Balde (5 Kg) | AS6: Balde (1 Kg) | AT6: Envases (250 g) | AU6: Mezclado | AV6: Coccion | AW6: Final
B7: 45898 | C7: Familiar | D7: SI | E7: 6.59 | F7: 15 | G7: 220 | H7: 46 | I7: 1.76 | J7: - | K7: 0.255 | L7: 0.066 | M7: 0.005 | N7: 0.44652778 | O7: 40 | P7: 2.8 | Q7: 1.8 | R7: 0.46180556 | S7: 53 | T7: 3.75 | U7: 2.8 | V7: - | W7: - | X7: - | Y7: - | Z7: - | AA7: - | AB7: - | AC7: - | AD7: - | AE7: - | AF7: - | AG7: - | AH7: - | AI7: - | AJ7: - | AK7: - | AL7: - | AM7: 71 | AN7: - | AO7: - | AP7: 97.6 | AQ7: =AP7/G7 -> 0.44363636 | AR7: 19.5 | AS7: - | AT7: - | AU7: 0.36805556 | AV7: 0.40277778 | AW7: -
B8: 45909 | C8: Repostero | D8: SI | E8: 6.44 | F8: 16 | G8: 240 | H8: 50 | I8: 3.84 | J8: 0.192 | K8: 0.36 | L8: 0.072 | M8: 0.005 | N8: - | O8: - | P8: - | Q8: - | R8: - | S8: - | T8: - | U8: - | V8: 0.47222222 | W8: 48 | X8: 3 | Y8: 2.2 | Z8: - | AA8: - | AB8: - | AC8: - | AD8: - | AE8: - | AF8: - | AG8: - | AH8: - | AI8: - | AJ8: - | AK8: - | AL8: - | AM8: - | AN8: - | AO8: - | AP8: 97 | AQ8: =AP8/G8 -> 0.40416667 | AR8: 19 | AS8: - | AT8: - | AU8: 0.35416667 | AV8: 0.38541667 | AW8: -
B9: 45910 | C9: Familiar | D9: SI | E9: 6.51 | F9: 16 | G9: 250 | H9: 52.5 | I9: 4 | J9: - | K9: 0.375 | L9: - | M9: 0.005 | N9: - | O9: - | P9: - | Q9: - | R9: - | S9: - | T9: - | U9: - | V9: - | W9: - | X9: - | Y9: - | Z9: - | AA9: - | AB9: - | AC9: - | AD9: - | AE9: - | AF9: - | AG9: - | AH9: - | AI9: - | AJ9: - | AK9: - | AL9: - | AM9: - | AN9: - | AO9: - | AP9: 125 | AQ9: =AP9/G9 -> 0.5 | AR9: 25 | AS9: - | AT9: - | AU9: - | AV9: - | AW9: -
B10: 45911 | C10: Repostero | D10: SI | E10: - | F10: - | G10: 240 | H10: 50 | I10: 3.82 | J10: 0.192 | K10: 0.36 | L10: 0.072 | M10: 0.005 | N10: 0.40625 | O10: 40 | P10: 3,1/2,4 | Q10: 1.5 | R10: 0.42083333 | S10: 48 | T10: 3.2 | U10: 1.5 | V10: 0.45208333 | W10: 50 / 51,2 | X10: 3,5 / 2,5 | Y10: 1.5 | Z10: 0.46458333 | AA10: 60 | AB10: 2,5 / 4,5 | AC10: 1.5 | AD10: 0.47222222 | AE10: 65 / 67 | AF10: 4,5 / 1,5 | AG10: 1.5 | AH10: 0.47847222 | AI10: 68 / 71,5 | AJ10: - | AK10: - | AL10: 0.48402778 | AM10: 72 / 76 | AN10: - | AO10: - | AP10: 110 | AQ10: =AP10/G10 -> 0.45833333 | AR10: 22 | AS10: - | AT10: - | AU10: - | AV10: 0.36805556 | AW10: 0.48611111
B11: 45912 | C11: Repostero | D11: SI | E11: 6.54 | F11: 15 | G11: 240 | H11: 50 | I11: 3.82 | J11: 0.192 | K11: 0.36 | L11: 0.072 | M11: 0.005 | N11: 0.40625 | O11: 45 / 46,1 | P11: 2,8 / 2,5 | Q11: 1.5 | R11: 0.41666667 | S11: 52 / 57,5 | T11: 3 / 2,5 | U11: 1 | V11: 0.44444444 | W11: 52 / 51,5 | X11: 2,5 / 2 | Y11: 1.5 | Z11: 0.45833333 | AA11: 59 / 60,7 | AB11: 2 | AC11: 1.5 | AD11: 0.46875 | AE11: 66 / 68,5 | AF11: 2 | AG11: 1.4 | AH11: 0.47569444 | AI11: 69 / 70 | AJ11: 1,8 / 2 | AK11: 1.5 | AL11: - | AM11: - | AN11: - | AO11: - | AP11: 90 | AQ11: =AP11/G11 -> 0.375 | AR11: 18 | AS11: - | AT11: - | AU11: 0.34027778 | AV11: 0.375 | AW11: 0.47916667
B12: 45913 | C12: Repostero | D12: SI | E12: 6.42 | F12: 15 | G12: 240 | H12: 50 | I12: 3.84 | J12: 0.192 | K12: 0.192 | L12: 0.072 | M12: 0.005 | N12: 0.39930556 | O12: 39 / 39,4 | P12: 4 / 2,75 | Q12: 1.5 | R12: 0.40972222 | S12: 46 / 45 | T12: 3,5 / 2,5 | U12: 1.5 | V12: 0.45208333 | W12: 46 / 49 | X12: 3 / 2,5 | Y12: 1.5 | Z12: 0.46666667 | AA12: 53 / 55 | AB12: 4,2 / 2,1 | AC12: 1.5 | AD12: 0.47638889 | AE12: 58 / 59,6 | AF12: 45692 | AG12: 1.5 | AH12: 0.48472222 | AI12: 64 / 65,3 | AJ12: - | AK12: - | AL12: 0.49305556 | AM12: 68 / 70,5 | AN12: - | AO12: - | AP12: 100 | AQ12: =AP12/G12 -> 0.41666667 | AR12: 19 | AS12: 5 | AT12: - | AU12: 0.34722222 | AV12: 0.36805556 | AW12: 0.49513889
B13: 45917 | C13: Familiar | D13: SI | E13: 6.61 | F13: 18 | G13: 240 | H13: 50 | I13: 1.92 | J13: - | K13: 0.28 | L13: 0.072 | M13: 0.006 | N13: 0.40972222 | O13: 37 | P13: 5 / 2,5 | Q13: 1.5 | R13: 0.4375 | S13: 51 | T13: 5/ 2,8 | U13: 1.6 | V13: 0.46180556 | W13: 55 | X13: 4,7 / 3 | Y13: 1.5 | Z13: 0.49444444 | AA13: 53 / 54 | AB13: 4 / 2,3 | AC13: 1.5 | AD13: 0.50277778 | AE13: 57 / 59 | AF13: - | AG13: - | AH13: - | AI13: - | AJ13: - | AK13: - | AL13: - | AM13: - | AN13: - | AO13: - | AP13: 102.75 | AQ13: =AP13/G13 -> 0.428125 | AR13: 11 | AS13: 4 | AT13: 175 | AU13: - | AV13: 0.36805556 | AW13: 0.50486111
B14: 45918 | C14: Repostero | D14: SI | E14: 6.56 | F14: 15 | G14: 244 | H14: 50 | I14: 3.84 | J14: 0.192 | K14: 0.36 | L14: 0.072 | M14: 0.005 | N14: 0.45347222 | O14: 37 / 38,7 | P14: 7,5 / 1,5 | Q14: 1.5 | R14: 0.48194444 | S14: 44 / 45,2 | T14: 4 / 1,6 | U14: 1.5 | V14: 0.51736111 | W14: 45 / 45,3 | X14: 4 / 1,6 | Y14: 1.5 | Z14: 0.53125 | AA14: 49 / 50,3 | AB14: 3,5 / 1,5 | AC14: 1.4 | AD14: 0.54236111 | AE14: 55 / 59,7 | AF14: 3,7 / 1,4 | AG14: 1.3 | AH14: 0.55069444 | AI14: 58 / 61 | AJ14: 3 / 1,5 | AK14: 1.5 | AL14: 0.51944444 | AM14: 63 / 66,1 | AN14: 2,7 / 1,8 | AO14: 1.6 | AP14: 107 | AQ14: =AP14/G14 -> 0.43852459 | AR14: 20 | AS14: 7 | AT14: - | AU14: 0.375 | AV14: 0.41319444 | AW14: 0.57013889
B15: 45919 | C15: Repostero | D15: SI | E15: 6.57 | F15: 16 | G15: 245 | H15: 50 | I15: 3.84 | J15: 0.192 | K15: 0.36 | L15: 0.072 | M15: 0.005 | N15: 0.42013889 | O15: 41 / 42,9 | P15: 3,2 / 1,8 | Q15: 1.5 | R15: 0.43402778 | S15: 43 / 43,5 | T15: 3 | U15: 1.5 | V15: 0.45208333 | W15: 42 / 41,4 | X15: 2,5 / 1,4 | Y15: 1.3 | Z15: 0.46666667 | AA15: 45 / 42,9 | AB15: 5 | AC15: 1.5 | AD15: 0.48402778 | AE15: 57 / 58 | AF15: 2,5 / 1,6 | AG15: 1.5 | AH15: 0.49166667 | AI15: 62 / 65 | AJ15: - | AK15: - | AL15: 0.50347222 | AM15: 59 / 72 | AN15: 3.5 | AO15: 1.5 | AP15: 100 | AQ15: =AP15/G15 -> 0.40816327 | AR15: 15 | AS15: 25 | AT15: - | AU15: 0.34722222 | AV15: 0.37430556 | AW15: -
B16: 45925 | C16: Repostero | D16: si | E16: 6.57 | F16: 15 | G16: 241 | H16: 50 | I16: 3.84 | J16: 0.192 | K16: 0.36 | L16: 0.072 | M16: 0.005 | N16: 0.42916667 | O16: 40 / 38,9 | P16: 4,5 / 1,8 | Q16: 1.5 | R16: 0.45347222 | S16: 48 / 49,7 | T16: 3,5 / 1,9 | U16: 1.5 | V16: 0.475 | W16: 50 / 51 | X16: 1.9 | Y16: 1.6 | Z16: 0.50138889 | AA16: 49 / 51 | AB16: 3 / 1,9 | AC16: 1.7 | AD16: 0.54097222 | AE16: 69 / 71 | AF16: - | AG16: - | AH16: - | AI16: - | AJ16: - | AK16: - | AL16: - | AM16: - | AN16: - | AO16: - | AP16: 97 | AQ16: =AP16/G16 -> 0.40248963 | AR16: 11 | AS16: 40 | AT16: - | AU16: 0.35416667 | AV16: 0.38194444 | AW16: -
B17: 46063 | C17: Repostero | F17: 16 | G17: 240 | H17: 40 | I17: 3.84 | J17: 0.15 | K17: 0.428 | L17: 0.15 | M17: 0.006 | N17: 0.41666667 | O17: 29,5/29,6 | P17: 2.6 | Q17: 2.1 | R17: 0.43055556 | S17: 34/34,3 | T17: 2 | U17: 1.9 | V17: 0.44444444 | W17: 39/38,7 | X17: 2.9 | Y17: 2.4 | Z17: 0.48611111 | AA17: 62/65,6 | AC17: 1.5 | AD17: 0.48958333 | AE17: 67/68,5 | AG17: 1.5 | AP17: 105.5 | AQ17: =AP17/G17 -> 0.43958333 | AR17: 21 | AS17: - | AT17: 2 | AU17: 0.35763889 | AV17: 0.375 | AW17: -
B18: 46064 | C18: Repostero | F18: 17 | G18: 240 | H18: 46 | I18: 3.84 | J18: 0.15 | K18: 0.429 | L18: 0.15 | M18: 0.006 | N18: 0.42708333 | O18: 33/32 | P18: 2,9/2,4 | Q18: 2.1 | R18: 0.44097222 | S18: 36/37,8 | T18: 2,9/2,4 | U18: 2.2 | V18: 0.45486111 | W18: 48/48,9 | X18: 2,5/2,2 | Y18: 2.1 | Z18: 0.46875 | AA18: 55,5/55 | AB18: 2,5/2,1 | AC18: 2.1 | AD18: 0.48263889 | AE18: 64/64,5 | AF18: 3/2,5 | AG18: 2.5 | AH18: 0.48958333 | AI18: 71 | AJ18: 3,4/2,8 | AK18: 2.8 | AL18: 0.51388889 | AM18: 65/66 | AN18: 3,3/2 | AO18: 1.5 | AP18: 103.7 | AQ18: =AP18/G18 -> 0.43208333 | AR18: 20 | AU18: 0.35763889 | AV18: 0.38541667
B19: 46067 | C19: Repostero | F19: 17 | G19: 250 | H19: 46 | I19: 3.84 | J19: 0.15 | K19: 0.523 | L19: 0.15 | M19: 0.006 | N19: 0.57986111 | O19: 30/28,5 | P19: 2,9/2,5 | Q19: 2 | R19: 0.59375 | S19: 34/35,3 | T19: 4/3,3 | U19: 2.2 | V19: 0.60763889 | W19: 39/38,7 | X19: 4/2,5 | Y19: 2.5 | Z19: 0.62152778 | AA19: 52 | AB19: - | AC19: - | AD19: 0.64375 | AE19: 62/61,2 | AQ19: =AP19/G19 -> 0
B20: 46073 | C20: Familiar | E20: 6.82 | F20: 14 | G20: 250 | H20: 43 | I20: 2.7 | J20: - | K20: 0.43 | L20: 0.15 | M20: 0.006 | N20: 0.48263889 | O20: 30/31 | Q20: 1.8 | R20: 0.51388889 | S20: 41,5/41,9 | T20: 3/2,4 | U20: 2.4 | V20: 0.52777778 | W20: 49/51 | X20: 3/2,50 | Y20: 2.2 | Z20: 0.55902778 | AA20: 62/64 | AB20: 2,8/1,8 | AC20: 1 | AD20: 0.55555556 | AE20: 65/67 | AF20: 2,70/1,8 | AG20: 1 | AP20: 80 | AQ20: =AP20/G20 -> 0.32 | AR20: 16 | AU20: 0.39583333 | AV20: 0.41666667
B21: 46079 | C21: Repostero | E21: 6.84 | F21: 18 | G21: 250 | H21: 46 | I21: 3.48 | J21: 0.15 | K21: 0.509 | L21: 0.15 | M21: 0.006 | N21: 0.47916667 | O21: 25/25,5 | P21: 3,00/2,00 | Q21: 1.5 | R21: 0.51041667 | S21: 35,5/37,5 | T21: 2,7/2,1 | U21: 2.1 | V21: 0.52777778 | W21: 45/45,4 | Y21: 2.5 | Z21: 0.54166667 | AA21: 52/51,7 | AB21: 3,5/3 | AC21: 2.5 | AD21: 0.55208333 | AE21: 60/62,80 | AF21: 4/1,5 | AG21: 1.1 | AH21: 0.5625 | AI21: 69/69,5 | AJ21: 4/1,5 | AK21: 1.1 | AP21: 100 | AQ21: =AP21/G21 -> 0.4 | AR21: 20
B22: 46080 | C22: Repostero | E22: 6.78 | F22: 16 | G22: 250 | H22: 46 | I22: 3.84 | J22: 0.15 | K22: 0.486 | L22: 0.15 | M22: 0.06 | N22: 0.42013889 | O22: 29/29,5 | P22: 3,8/2 | Q22: 2 | R22: 0.43055556 | S22: 31/31,6 | T22: 3,9/2,4 | U22: 2 | V22: 0.45486111 | W22: 38/38 | X22: 3/2,5 | Y22: 2.5 | Z22: 0.47222222 | AA22: 46/46,8 | AB22: 3/2,4 | AC22: 2.4 | AD22: 0.48611111 | AE22: 52/52,5 | AF22: 2,5/2,4 | AG22: 2 | AH22: 0.5 | AI22: 55/55,2 | AJ22: 3/2,5 | AK22: 1.5 | AL22: 0.51388889 | AM22: 65/65,3 | AN22: 2,5/2 | AO22: 1.5 | AP22: 106 | AQ22: =AP22/G22 -> 0.424 | AR22: 21
B23: 46085 | C23: Repostero | E23: 6.62 | F23: 17 | G23: 120 | H23: 46 | I23: 3480 | J23: 150 | K23: 0.456 | L23: 175 | M23: 0.006 | N23: 0.54861111 | O23: 31,5/33,5 | P23: 2/1,8 | Q23: 1.7 | R23: 0.56944444 | S23: 40/41,7 | T23: 2,2/1,8 | U23: 1.9 | V23: 0.58333333 | W23: 47/48,9 | X23: 2,2/1,8 | Y23: 1.9 | Z23: 0.59722222 | AA23: 48/48,8 | AB23: 2,1/1,9 | AC23: 1.9 | AD23: 0.61111111 | AE23: 55/57,8 | AF23: 2/1,5 | AG23: 1.5 | AH23: 0.625 | AI23: 53/56,2 | AJ23: 1,8/1,7 | AK23: 1.5 | AL23: 0.64583333 | AM23: 64/67,5 | AN23: 1,4/1,1 | AO23: 1.1 | AP23: 85 | AQ23: =AP23/G23 -> 0.70833333 | AR23: 17

Sheet STOCK DLCH
A1: DULCE LECHE FAMILIAR | K1: DULCE DE LECHE REPOSTRERO
H2: PESO | I2: CANTIDAD | S2: CANTIDAD | T2: PESO (KG)
A3: LOTE | B3: PRESENTACION | C3: CANTIDAD (UDS) | D3: PESO (KG) | F3: TOTAL | G3: 250 G | H3: =SUM(D4:D6) -> 103.5 | I3: =+SUM(C4:C6) -> 414 | K3: LOTE | L3: PRESENTACION | M3: CANTIDAD (UDS) | N3: PESO (KG) | Q3: TOTAL | R3: 1KG | S3: =+SUM(M4) -> 44 | T3: =+SUM(N4) -> 44
A4: 1212250945FL | B4: 250 G | C4: 169 | D4: 42.25 | G4: 5KG | H4: =+SUM(D7) -> 80 | I4: =+C7 -> 16 | K4: 0511250730RL | L4: 1 KG | M4: 44 | N4: 44 | R4: 5KG | S4: =+SUM(M5:M6) -> 41 | T4: =+SUM(N5:N6) -> 205
A5: 1301261200FL | B5: 250 G | C5: =142-H8 -> 136 | D5: =+C5*0.25 -> 34 | K5: 2602260900RL | L5: 5 KG | M5: 20 | N5: 100
A6: 2002260900FL | B6: 250G | C6: 109 | D6: 27.25 | F6: DESPACHO | K6: 2702260820RL | L6: 5KG | M6: 21 | N6: =21*5 -> 105 | Q6: DESPACHO
B7: 5KG | C7: 16 | D7: 80 | F7: FECHA | G7: LOTE | H7: CANTIDAD | I7: PRESENTACION | Q7: FECHA | R7: LOTE | S7: CANTIDAD | T7: PRESENTACION
F8: 46080 | G8: =+A5 -> 1301261200FL | H8: 6 | I8: 250 G

Sheet Registro de cheddar
A3: FECHA | B3: LOTE | C3: CANTIDAD (BOLSAS) | D3: PESO TOTAL (KG) | E3: PESADO DE MATERIA, ADITIVOS Y CONSERVANTES | T3: ENVASADO
E4: SUERO EN POLVO (KG) | F4: AGUA (KG) | G4: CUAJADA (KG) | H4: SAL ICL (KG) | I4: MANTEQUILLA (KG) | J4: GELATINA EN POLVO (KG) | K4: PERFECTAMYL EN GEL (KG) | L4: ACIDO LACTICO 10 % (KG) | M4: ACIDO FOSFORICO 10 % (KG) | N4: ACIDO CITRICO 10 % (KG) | O4: SORBATO DE POTASIO (KG) | P4: SABOR CHEDDAR (KG) | Q4: COLOR (KG) | R4: AROMA/ESENCIA (KG) | S4: SAL (KG) | T4: TEMPERATURA (°C) | U4: HORA INICIAL | V4: HORA FINAL
A5: 46055 | B5: 0202261200CHL | C5: 41 | D5: 43.3 | E5: 1.453 | F5: 10 | G5: 23 | H5: 0.759 | I5: 10.4 | J5: 0.145 | K5: 1.453 | L5: 0.18 | M5: 0.025 | N5: 0.015 | O5: 0.065 | P5: 0.216 | Q5: 0.28 | R5: 0.025 | S5: 0.05 | T5: 65 | U5: 0.60347222 | V5: 0.62361111
A6: 46055 | B6: 0202261500CHL | C6: 44 | D6: 47 | E6: 1.453 | F6: 9 | G6: 23 | H6: 0.759 | I6: 10.4 | J6: 0.145 | K6: 1.453 | L6: 0.091 | M6: 0.011 | N6: 0.046 | O6: 0.065 | P6: 0.216 | Q6: 0.256 | R6: 0.025 | S6: - | T6: 58 | U6: 0.68819444 | V6: 0.71111111
A7: 46057 | B7: 040226 | C7: 45 | E7: 1.453 | F7: 9.5 | G7: 23 | H7: 0.759 | I7: 10.4 | J7: 0.145 | K7: 1.453 | L7: 0.18 | M7: 0.025 | N7: 0.02 | O7: 0.065 | P7: 0.216 | Q7: 0.28 | R7: 0.025 | S7: - | T7: 61 | U7: 0.57638889 | V7: 0.60069444
A8: 46057 | B8: 040226 | E8: 1.453 | F8: 9 | G8: 23 | H8: 0.759 | I8: 10.4 | J8: 0.145 | K8: 1.453 | L8: 0.21 | M8: 0.025 | N8: 0.06 | O8: 0.065 | P8: 0.216 | Q8: 0.28 | R8: 0.025 | S8: - | T8: 59 | U8: 0.66666667 | V8: 0.6875
A9: 46058 | B9: 0502260900CHL | C9: 46 | E9: 1.453 | F9: 8.5 | G9: 23 | H9: 0.759 | I9: 10.4 | J9: 0.145 | K9: 1.453 | L9: 0.2 | M9: 0.035 | N9: 0.032 | O9: 0.065 | P9: 0.216 | Q9: 0.28 | R9: 0.035 | T9: 58 | U9: 0.40972222 | V9: 0.43402778
A10: 46063 | B10: 1002261400CHL | C10: 46 | E10: 1.225 | F10: 7.58 | G10: 23 | H10: 0.64 | I10: 8.9 | J10: 0.122 | K10: 1.225 | L10: 0.76 | M10: 0 | N10: 0.012 | O10: 0.055 | P10: 0.182 | Q10: 0.236 | R10: 0.021 | S10: - | T10: 55 | U10: 0.66666667 | V10: 0.6875
A11: 46064 | B11: 1102261400CHL | C11: 40 | E11: 1.14 | F11: 6 | G11: 18 | H11: 0.595 | I11: 8.2 | J11: 0.114 | K11: 1.14 | L11: 0.071 | M11: 0 | N11: 0.012 | O11: 0.051 | P11: 0.169 | Q11: 0.191 | R11: 0.016 | S11: 0.047 | U11: 0.66666667 | V11: 0.69097222
A12: 46065 | B12: 1202261000CHL | C12: 37 | E12: 1.135 | F12: 6 | G12: 18 | H12: 0.593 | I12: 8.2 | J12: 0.113 | K12: =1.135+0.37 -> 1.505 | L12: 0 | M12: 0 | N12: 0.012 | O12: 0.051 | P12: 0.213 | Q12: 0.196 | R12: 0.021 | S12: - | U12: 0.49305556 | V12: 0.51319444
A13: 46065 | B13: 1202261430CHL | C13: 38 | E13: 1.135 | F13: 6.5 | G13: 23 | H13: 0.593 | I13: 8.2 | J13: 0.113 | K13: 1.135 | L13: 0 | M13: 0 | N13: 0.012 | O13: 0.051 | P13: 0.213 | Q13: 0.196 | R13: 0.021 | S13: 0.06 | U13: 0.59375 | V13: 0.61388889
A14: 46066 | B14: 1302261400CHL | C14: 32 | D14: 34.55 | E14: 1.135 | H14: 0.593 | I14: 8.2 | J14: 0.113 | K14: 1.135 | L14: - | M14: - | N14: 0.012 | O14: 0.051 | P14: 0.216 | Q14: 0.196 | R14: 0.021 | S14: -
A15: 46065 | B15: 1202261600CHL | C15: 38 | E15: 1.141 | F15: 6 | G15: 18 | H15: 0.596 | I15: 8.2 | J15: 0.114 | K15: 1.143 | L15: - | M15: - | N15: 0.012 | O15: 0.051 | P15: 0.17 | Q15: 0.192 | R15: 0.016 | S15: 0.047
A16: 46066 | B16: 1302260800CHL | C16: 41 | D16: 40.35 | E16: 1.169 | F16: 5.5 | G16: 23 | H16: 0.595 | I16: 8.4 | J16: 0.117 | K16: 1.1171 | L16: - | M16: - | N16: 0.012 | O16: 0.052 | P16: 0.174 | Q16: 0.216 | R16: 0.017 | S16: - | T16: 60 | U16: 0.62152778 | V16: 0.64444444
A17: 46066 | B17: 1302261100CHL | C17: 35 | E17: 1.169 | F17: 5.5 | G17: 18.5 | H17: 0.595 | I17: 8.4 | J17: 0.117 | K17: 1.171 | L17: - | M17: - | N17: 0.012 | O17: 0.052 | P17: 0.174 | Q17: 0.216 | R17: 0.016 | S17: 0.048 | T17: 54
A18: 46066 | B18: 1302261400CHL | C18: 32 | D18: 34.55 | E18: 1.161 | F18: 6 | G18: =18+5 -> 23 | H18: 0.607 | I18: 8.4 | J18: 0.116 | K18: 1.164 | L18: - | M18: - | N18: 0.012 | O18: 0.052 | P18: 0.173 | Q18: 0.217 | R18: 0.016 | S18: -
A19: 46071 | B19: 1802261100CHL | C19: 41.5 | D19: 47.8 | E19: 1.169 | F19: 6 | G19: 23 | H19: 0.611 | I19: 8.4 | J19: 0.117 | K19: 1.171 | L19: - | M19: - | N19: 0.012 | O19: 0.052 | P19: 0.174 | Q19: 0.216 | R19: 0.016 | S19: 0.075
A20: 46071 | B20: 1808261330CHL | C20: 42 | D20: 48.95 | E20: 1.143 | F20: 6 | G20: 23 | H20: 0.597 | I20: 8.2 | J20: 0.114 | K20: 1.1146 | L20: 0.071 | M20: - | N20: 0.012 | O20: 0.051 | P20: 0.17 | Q20: 0.22 | R20: 0.025 | S20: -
A21: 46072 | B21: 1902261000CHL | C21: 40 | D21: 45.75 | E21: 1.135 | F21: 6 | G21: 23 | H21: 0.593 | I21: 8.4 | J21: 0.113 | K21: 1.137 | L21: - | M21: - | N21: 0.012 | O21: 0.052 | P21: 0.216 | Q21: 0.22 | R21: 0.025 | S21: -
A22: 46072 | B22: 1902261300CHL | C22: 43 | D22: 50 | E22: 1.143 | F22: 6 | G22: =23+5 -> 28 | H22: 0.595 | I22: 8.4 | J22: 0.116 | K22: 1.143 | L22: 0.083 | M22: - | N22: 0.014 | O22: 0.052 | P22: 0.216 | Q22: 0.22 | R22: 0.025 | S22: - | T22: 54
A23: 46076 | B23: 2302261000CHL | C23: 42 | D23: 47.35 | E23: 1.143 | F23: 6 | G23: 26 | H23: 0.595 | I23: 8.4 | J23: 0.116 | K23: 1.143 | L23: 0.124 | M23: 0.023 | N23: 0.014 | O23: 0.052 | P23: 0.216 | Q23: 0.22 | R23: 0.025 | S23: 0.055 | T23: 57 | U23: 0.49305556 | V23: 0.51388889
A24: 46076 | B24: 2302261300CHL | C24: 35 | D24: 40.95 | E24: 1.143 | F24: 6 | G24: 20 | H24: 0.595 | I24: 8.4 | J24: 0.116 | K24: 1.143 | L24: 0.18 | M24: 0.02 | N24: 0.014 | O24: 0.052 | P24: 0.216 | Q24: 0.2 | R24: 0.025 | S24: - | T24: 54 | U24: 0.60069444 | V24: 0.62638889
A25: 46076 | B25: 2302261530CHL | E25: 1.143 | F25: 6 | G25: 23 | H25: 0.595 | I25: 8.4 | J25: 0.116 | K25: 1.143 | L25: 0.124 | M25: 0.023 | N25: 0.014 | O25: 0.052 | P25: 0.216 | Q25: 0.216 | R25: 0.025 | S25: -
A26: 46078 | B26: 2502260930CHL | C26: 35 | D26: 39.95 | E26: 1.143 | F26: 6 | G26: 23 | H26: 0.595 | I26: 8.4 | J26: 0.116 | K26: 1.143 | L26: - | M26: - | N26: 0.04 | O26: 0.052 | P26: 0.216 | Q26: 0.19 | R26: 0.035 | S26: 0.03 | T26: 57 | U26: 0.43888889 | V26: 0.45486111
A27: 46078 | B27: 2502261130CHL | C27: 49 | D27: 48.3 | E27: 1.143 | F27: 6 | G27: 27 | H27: 0.595 | I27: 8.4 | J27: 0.116 | K27: 1.143 | L27: - | M27: - | N27: 0.012 | O27: 0.052 | P27: 0.24 | Q27: 0.22 | R27: 0.035 | S27: 0.04 | T27: 56 | U27: 0.52708333 | V27: 0.55
A28: 46078 | B28: 2502261330CHL | C28: 37 | D28: 41.55 | E28: 1.143 | F28: 6 | G28: 18 | H28: 0.595 | I28: 8.4 | J28: 0.116 | K28: 1.143 | L28: 0.18 | M28: 0.02 | N28: 0.012 | O28: 0.052 | P28: 0.24 | Q28: 0.19 | R28: 0.03 | S28: 0.04 | T28: 55 | U28: 0.61597222 | V28: 0.63888889
A29: 46079 | B29: 2602261530CHL | C29: 41 | D29: 46.25 | E29: 1.143 | F29: 6 | G29: 27 | H29: 0.595 | I29: 8.4 | J29: 0.116 | K29: 1.143 | L29: 0.09 | M29: 0.01 | N29: 0.012 | O29: 0.052 | P29: 0.216 | Q29: 0.22 | R29: 0.025 | S29: 0.055 | T29: 55 | U29: 0.69791667 | V29: 0.71527778
A30: 46080 | B30: 2702261400CHL | E30: 1.143 | F30: 6 | G30: 18 | H30: 0.595 | I30: 8.4 | J30: 0.116 | K30: 1.143 | L30: 0.18 | M30: 0.02 | N30: 0.012 | O30: 0.052 | P30: 0.216 | Q30: 0.18 | R30: 0.025 | S30: - | T30: 55 | U30: 0.61180556 | V30: 0.63541667

Sheet STOCK QCHL
A2: N° | B2: LOTE | C2: CANTIDAD (UDS) | D2: PESO(KG) | F2: TOTAL | G2: CANTIDAD (UDS) | H2: PESO (KG) | K2: DESPACHO
A3: 1 | B3: 1902261300CHL | C3: 23 | D3: 25.2 | G3: =+SUM(C3:C9) -> 255 | H3: =+SUM(D3:D9) -> 281.67 | K3: N° | L3: FECHA | M3: LOTE | N3: CANTIDAD | O3: PESO
A4: 2 | B4: 2302261300CHL | C4: 35 | D4: 40.87 | K4: 1
A5: 2 | B5: 2302261530CHL | C5: 35 | D5: 39.55 | K5: 2 | L5: 46087 | M5: =+B8 -> 2502261330CHL | N5: =+C8 -> 37 | O5: =+D8 -> 41.55
A6: 3 | B6: 2502260930CHL | C6: 35 | D6: 39.95 | K6: 3 | L6: 46087 | M6: =+B6 -> 2502260930CHL | N6: 9 | O6: 9.15
A7: 4 | B7: 2502261130CHL | C7: 49 | D7: 48.3 | K7: 4
A8: 5 | B8: 2502261330CHL | C8: 37 | D8: 41.55 | E8: LOTE VENDIDO | K8: 5
A9: 6 | B9: 2602261530CHL | C9: 41 | D9: 46.25 | K9: 6
K10: 7

Sheet CUAJADA
A1: FECHA | B1: LOTE | C1: VOLUMEN DE LECHE | D1: PH INICIAL | E1: HORA INICIAL | F1: HORA AGREGADO FERMENTO | G1: MASA DE FERMENTO | H1: MARCA FERMENTO | I1: PH AGREGADO DE FERMENTO | J1: TEMPERATURA | K1: MASA CaCl2 [g] | L1: HORA DE AGREGADO CaCl2 | M1: HORA DE AGREGADO DE CUAJO | N1: masa de cuajo [g] | O1: ph inicial | P1: temperaturafinal | Q1: Hora corte de cuajada | R1: Temperatura final | S1: ph final | T1: hora de vaciado | U1: hora inicial de preprensado | V1: hora final de ingreso a camara | W1: ph final de ingreso a camara | X1: temperatura | Y1: MASA PRENSADA | Z1: MASA CUAJADA | BQ1: masa total cuajada | BR1: RELACION LECHE/CUAJADA
A2: 46003 | B2: 121225STM | C2: 2700 | D2: 6,53/32,2 | E2: 0.38611111 | F2: 0.45763889 | G2: 2 BOLSAS DE 1000 | H2: ST081SACCO | I2: 6.55 | J2: 36.7 | K2: 532 | L2: 0.46736111 | M2: 0.46875 | N2: 42/43 | O2: 6.49 | P2: 36.7 | Q2: 0.51041667 | R2: 45 | S2: 6.07 | T2: 0.55555556 | U2: 0.56944444 | V2: 0.57986111 | W2: 5.44 | X2: 43
A3: 46004 | B3: 131225 | C3: 2900 | D3: 6,5/36,8 | E3: 0.36041667 | F3: 0.41875 | G3: 3 bolsas | H3: ST081SACCO | I3: 6.53 | J3: 36.6 | K3: 530 | L3: 0.42638889 | M3: 0.43055556 | N3: 48 | O3: 6.51 | P3: 36.5 | Q3: 0.45833333 | R3: 43.5 | S3: 6.27 | T3: 0.47916667 | U3: 0.49861111 | V3: 0.51388889 | W3: 5.97 | X3: 42
A4: 46008 | B4: 1712251047 | C4: 3000 | D4: 6.64 | E4: 0.44930556 | F4: 0.52569444 | G4: 2 | H4: ST081SACCO | I4: 6,68/6,64 | J4: 36.8 | K4: 500 | L4: 0.53333333 | M4: 0.53819444 | N4: 48 | O4: 6.59 | P4: 36.8 | Q4: 0.56944444 | R4: 43 | S4: 6.4 | T4: 0.62013889 | U4: 0.63680556 | V4: 0.65277778 | W4: 5.64 | X4: 43
A5: 46009 | B5: 1812250854 | C5: 2900 | D5: 6,93/6,84 | E5: 0.37083333 | F5: 0.42916667 | G5: 2 | H5: ST081SACCO | I5: 6.63 | J5: 36.5 | K5: 530 | L5: 0.44513889 | M5: 0.44652778 | N5: 45 | O5: 6.6 | P5: 36.6 | Q5: 0.47708333 | R5: 46.6 | V5: 0.55486111 | W5: 5.42 | X5: 45
A6: 46010 | B6: 1912250906 | C6: 2750 | E6: 0.37916667 | F6: 0.45833333 | G6: 2 | H6: ST081SACCO | I6: 6.64 | J6: 36.5 | K6: 344 | L6: 0.47986111 | M6: 0.48125 | N6: 44 | O6: 6.59 | P6: 36.5 | Q6: 0.50763889 | T6: 0.5375 | U6: 0.55555556 | V6: 0.56805556 | W6: 5.8 | X6: 44.2
A7: 46011 | B7: 2012250850 | C7: 2820 | D7: 6,58/37 | E7: 0.36805556 | F7: 0.43055556 | G7: 2 | H7: ST081SACCO | I7: 6.58 | J7: 36.6 | K7: 330 | L7: 0.45069444 | M7: 0.45138889 | N7: 44.5 | O7: 6.57 | P7: 36.6 | Q7: 0.48819444 | R7: 43 | S7: 5.93 | T7: 0.53333333
A8: 46014 | B8: 2312251130 | C8: 3000 | D8: 6.83 | F8: 0.53125 | G8: =50*2 -> 100 | H8: criollo | I8: 6,14/6,83 | J8: 36 | M8: 0.56319444 | N8: 61.5 | P8: 37 | Q8: 0.59583333 | R8: 41.8 | T8: 0.625
A9: 46030 | B9: 801261100 | C9: 3000 | D9: 6.54 | E9: 11:00:00 | F9: 0.53819444 | G9: 50 | H9: HANSEN | I9: 6.51 | J9: 36.4 | K9: 60 | L9: 0.53958333 | M9: 0.54722222 | N9: 34 | O9: 6.5 | P9: 36.3 | Q9: 0.57986111 | R9: 41 | S9: 6.07 | T9: 0.58541667 | U9: 0.59722222 | V9: 0.63888889 | W9: 5.7 | X9: 40.7 | Y9: 212.25 | Z9: 205.35 | BQ9: =SUM(Y9:BP9) -> 417.6 | BR9: =C9/BQ9 -> 7.183908
A10: 46031 | B10: 90126 | C10: 3000 | D10: 6.6 | E10: 0.38888889 | F10: 0.4875 | G10: 1.5 | H10: HANSEN | I10: 6.56 | J10: 36.1 | K10: 60 | L10: 0.48819444 | M10: 0.49722222 | N10: 34 | O10: 6.56 | P10: 36.1 | Q10: 0.54166667 | R10: 40.5 | S10: 6.46 | T10: 0.57013889 | U10: 0.58333333 | V10: 0.61458333 | W10: 6.46 | X10: 40.5 | Y10: 7.55 | Z10: 7.1 | AA10: 7.3 | AB10: 6.48 | AC10: 6.6 | AD10: 6.9 | AE10: 6.4 | AF10: 6.8 | AG10: 6.9 | AH10: 6.2 | AI10: 7.25 | AJ10: 7.2 | AK10: 6.95 | AL10: 5.9 | AM10: 5.85 | AN10: 4.8 | AO10: 6.95 | AP10: 6.2 | AQ10: 5.65 | AR10: 4.1 | AS10: 5.85 | AT10: 7.4 | AU10: 7.2 | AV10: 5.3 | AW10: 6 | AX10: 5.85 | AY10: 5.25 | AZ10: 6.05 | BA10: 6.2 | BB10: 7.1 | BC10: 6.95 | BD10: 7.3 | BE10: 6.6 | BF10: 18.6 | BG10: 17.25 | BH10: 15.95 | BI10: 23.2 | BJ10: 16.1 | BK10: 17.7 | BL10: 20.75 | BM10: 16.7 | BN10: 20.55 | BO10: 23.55 | BP10: 18.1 | BQ10: =SUM(Y10:BP10) -> 420.58 | BR10: =C10/BQ10 -> 7.1330068
A11: 46032 | B11: 100126 | C11: 2750 | D11: 6.57 | E11: 0.36111111 | F11: 0.43263889 | G11: p/1500 | H11: HANSEN | I11: 6.57 | J11: 36.1 | K11: 60 | L11: 0.43333333 | M11: 0.43958333 | N11: 34.5 | O11: 6.54 | P11: 36.1 | Q11: 0.47430556 | R11: 41.1 | S11: 6.06 | T11: 0.50833333 | U11: 0.53125 | V11: 0.57638889 | W11: 5.95 | X11: 40.6 | Y11: 6.9 | Z11: 7.1 | AA11: 6.7 | AB11: 6.6 | AC11: 7.65 | AD11: 6.8 | AE11: 6.85 | AF11: 6.65 | AG11: 6.95 | AH11: 6.65 | AI11: 7 | AJ11: 6.85 | AK11: 7.05 | AL11: 6.6 | AM11: 6.05 | AN11: 7.2 | AO11: 7 | AP11: 6.8 | AQ11: 6.65 | AR11: 7.9 | AS11: 6.65 | AT11: 6.85 | AU11: 7 | AV11: 7.6 | AW11: 6.5 | AX11: 6.85 | AY11: 6.15 | AZ11: 7.35 | BA11: 6.8 | BB11: 6.65 | BC11: 17.3 | BD11: 16.5 | BE11: 19.5 | BF11: 20.2 | BG11: 20.25 | BH11: 16.85 | BI11: 17.5 | BJ11: 15.55 | BK11: 15.8 | BL11: 16.55 | BQ11: =SUM(Y11:BP11) -> 382.35 | BR11: =C11/BQ11 -> 7.192363
A12: 46035 | B12: 13012026 | C12: 2850 | D12: 6.9 | F12: 0.55138889 | G12: 50 | H12: HANSEN | I12: 6.66 | J12: 36.7 | K12: 250 | L12: 0.55277778 | M12: 0.55902778 | N12: 35 | O12: 661 | P12: 36.7 | Q12: 0.58888889 | R12: 40.5 | S12: 6.6 | T12: 0.62638889 | U12: 0.64930556 | V12: 0.68263889 | W12: 6.19 | X12: 36.5 | Y12: 22.6 | Z12: 20.8 | AA12: 24.95 | AB12: 24.65 | AC12: 23.6 | AD12: 22.15 | AE12: 24.1 | AF12: 21.35 | AG12: 25.7 | AH12: 22.6 | AI12: 22.45 | AJ12: 23.8 | AK12: 24.45 | AL12: 21.6 | AM12: 9.7 | AN12: 22.65 | AO12: 25.4 | AP12: 23.6 | BQ12: =SUM(Y12:BP12) -> 406.15 | BR12: =C12/BQ12 -> 7.0171119
A13: 46036 | B13: 14012026 | C13: =1600+1500 -> 3100 | D13: 664/664 | E13: 9:00/9:52 | F13: 10:02/10:48 | G13: 25/25 | H13: HANSEN | I13: 6,64/6,64 | J13: 36,1/35,5 | K13: 160/150 | L13: 10:02/10:53 | M13: 10:20/11:17 | N13: 20/24 | O13: 6,61/6,6 | P13: 36,1/37,2 | Q13: 11:00/12:00 | R13: 43/44 | S13: 6,3/6,53 | T13: 11:55/13:15 | U13: 12/13:35 | V13: 13:40/14:30 | W13: 5,85/5,55 | X13: 39/39 | Y13: 29.9 | Z13: 29.7 | AA13: 25.45 | AB13: 19.45 | AC13: 26.15 | AD13: 21.15 | AE13: 20.9 | AF13: 24.8 | AG13: 22.1 | AH13: 22.85 | AI13: 14.2 | AJ13: 20.55 | AK13: 19.15 | AL13: 18.7 | AM13: 21.65 | AN13: 18.25 | AO13: 16.85 | AP13: 19.75 | AQ13: 18.35 | AR13: 20.95 | AS13: 19.2 | AT13: 23.95 | AU13: 8.15 | BQ13: =SUM(Y13:BP13) -> 482.15 | BR13: =C13/BQ13 -> 6.4295344
A14: 46037 | B14: 15012026 | C14: 2950 | D14: 6.58 | E14: 0.4375 | F14: 12;10 | G14: 50 | H14: HANSEN | I14: 6.57 | J14: 36 | K14: 301 | L14: 0.50972222 | M14: 0.5125 | N14: 48 | O14: 6.56 | P14: 36 | Q14: 0.54652778 | R14: 40.9 | T14: 0.58402778 | U14: 0.60347222 | V14: 0.68402778 | W14: 5.62 | X14: 38 | Y14: 19.55 | Z14: 26.35 | AA14: 24.5 | AB14: 21.25 | AC14: 22.9 | AD14: 24.15 | AE14: 24.5 | AF14: 24.45 | AG14: 23.45 | AH14: 21.25 | AI14: 23.35 | AJ14: 23.25 | AK14: 25.45 | AL14: 20.35 | AM14: 22.45 | BQ14: =SUM(Y14:BP14) -> 347.2 | BR14: =C14/BQ14 -> 8.4965438
A15: 46038 | B15: 16012026 | C15: 3000 | D15: 6.63 | E15: 0.375 | F15: 0.42986111 | G15: 5 | H15: HANSEN | I15: 6.66 | J15: 335.5 | K15: 300 | L15: 0.44097222 | M15: 0.45208333 | N15: 42.5 | O15: 6.63 | P15: 35.7 | Q15: 0.48263889 | R15: 39.9 | S15: 6.49 | T15: 0.51875 | U15: 0.54166667 | V15: 0.59722222 | W15: 5.77 | X15: 39 | Y15: 28.1 | Z15: 21 | AA15: 24.05 | AB15: 22.85 | AC15: 24.7 | AD15: 27.9 | AE15: 26.05 | AF15: 22.9 | AG15: 21.65 | AH15: 21.35 | AI15: 21.4 | AJ15: 21.05 | AK15: 24.55 | AL15: 17.9 | AM15: 25.25 | BQ15: =SUM(Y15:BP15) -> 350.7 | BR15: =C15/BQ15 -> 8.5543199
A16: 46039 | B16: 17012026 | C16: =1800+1300 -> 3100 | D16: 6,57/6,57 | E16: 8:20/9:10 | F16: 9:16/9:18 | G16: 50/25 | H16: HANSEN | I16: 6,57/6,57 | J16: 34,8/35,5 | K16: 280/120 | L16: 09:17:00/9:56 | M16: 9:39/10:38 | N16: 29/19 | O16: 6,56/6,60 | P16: 35,5/35 | Q16: 0.4375 | R16: 42/43 | V16: 0.575 | W16: 5.6 | X16: 41 | Y16: 19.9 | Z16: 21.8 | AA16: 22.9 | AB16: 19.85 | AC16: 19.75 | AD16: 24.3 | AE16: 21.25 | AF16: 26.45 | AG16: 22.65 | AH16: 23.35 | AI16: 22 | AJ16: 26.75 | AK16: 25.1 | AL16: 21.1 | AM16: 50.45 | AN16: 39.45 | AO16: 49.5 | BQ16: =SUM(Y16:BP16) -> 456.55 | BR16: =C16/BQ16 -> 6.7900559
A17: 46042 | B17: 20012026 | C17: 3000 | E17: 0.43055556 | F17: 0.46736111 | G17: 50 | H17: HANSEN | I17: 7.28 | J17: 36 | K17: 300 | L17: 0.46944444 | M17: 0.50138889 | N17: 48 | O17: 7.29 | P17: 36.8 | Q17: 0.54513889 | R17: 36.5 | S17: 7.2 | T17: 0.56597222 | U17: 13 | Y17: 21.85 | Z17: 23.75 | AA17: 16.65 | AB17: 21.7 | AC17: 24.35 | AD17: 25.4 | AE17: 23.6 | AF17: 24.25 | AG17: 26.7 | AH17: 24.7 | AI17: 28.6 | AJ17: 25.2 | AK17: 30.05 | AL17: 22.75 | AM17: 27.8 | AN17: 26.35 | BQ17: =SUM(Y17:BP17) -> 393.7 | BR17: =C17/BQ17 -> 7.6200152
A18: 46043 | B18: 21012026 | C18: 3000 | E18: 0.36458333 | F18: 0.4125 | G18: 50 | H18: HANSEN | J18: 36.7 | K18: 450 | L18: 0.44166667 | M18: 0.45138889 | N18: 54.5 | P18: 36.6 | Q18: 0.47777778 | R18: 41 | T18: 0.50902778 | U18: 0.52777778 | V18: 0.61111111 | X18: 43.7 | Y18: 25.45 | Z18: 24.05 | AA18: 31.05 | AB18: 25.15 | AC18: 22.7 | AD18: 25.1 | AE18: 24.85 | AF18: 34.45 | AG18: 31.6 | AH18: 24.05 | AI18: 24.05 | AJ18: 27.2 | AK18: 25.6 | AL18: 26.35 | BQ18: =SUM(Y18:BP18) -> 371.65 | BR18: =C18/BQ18 -> 8.0721109
A19: 46044 | B19: 22012026 | C19: 2700 | E19: 0.375 | F19: 0.42291667 | G19: 50 | H19: HANSEN | I19: 6.74 | J19: 35.6 | K19: 405 | L19: 0.43819444 | M19: 0.44444444 | N19: 200 | O19: 6.69 | P19: 36.5 | Q19: 0.47430556 | R19: 42 | S19: 6.67 | T19: 0.5 | U19: 0.52083333 | V19: 0.58263889 | W19: 5.8 | X19: 43.01 | Y19: 22.05 | Z19: 24 | AA19: 16.3 | AB19: 21.2 | AC19: 21.1 | AD19: 24.55 | AE19: 19.2 | AF19: 24.15 | AG19: 30 | AH19: 21.4 | AI19: 23.15 | AJ19: 25.55 | AK19: 23.95 | AL19: 22.4 | BQ19: =SUM(Y19:BP19) -> 319 | BR19: =C19/BQ19 -> 8.4639498
A20: 46045 | B20: 23012026 | C20: 2400 | E20: 0.52083333 | F20: 0.54375 | G20: 50 | H20: HANSEN | I20: 6.57 | J20: 34 | K20: 377 | L20: 0.54861111 | M20: 0.58541667 | N20: 20.5 | O20: 6.48 | P20: 36.32 | Q20: 0.61319444 | R20: 40.01 | S20: 6.4 | T20: 0.64097222 | U20: 0.66319444 | V20: 0.71527778 | W20: 5.55 | X20: 41.8 | Y20: 24.35 | Z20: 23.35 | AA20: 24.6 | AB20: 23.65 | AC20: 25.4 | AD20: 22.45 | AE20: 25.95 | AF20: 26.1 | AG20: 20.75 | AH20: 21.95 | AI20: 28.3 | AJ20: 26.15 | AK20: 26 | BQ20: =SUM(Y20:BP20) -> 319 | BR20: =C20/BQ20 -> 7.523511
A21: 46046 | B21: 24012026 | E21: 0.36458333 | F21: 0.39027778 | G21: 50 | H21: HANSEN | I21: 6.64 | J21: 33.5 | K21: 310 | L21: 0.39444444 | M21: 0.41666667 | N21: 41.5 | O21: 6.63 | P21: 36.52 | Q21: 0.44444444 | R21: 41.6 | S21: 6.61 | T21: 0.47083333 | V21: 0.54375 | W21: 5.89 | X21: 41.3 | Y21: 26.9 | Z21: 25.1 | AA21: 26.9 | AB21: 27.05 | AC21: 49.95 | AD21: 51.25 | AE21: 57.3 | AF21: 50.55 | AG21: 54.85 | BQ21: =SUM(Y21:BP21) -> 369.85 | BR21: =C21/BQ21 -> 0
A22: 46049 | B22: 27012026 | C22: 2600 | E22: 0.34722222 | F22: 0.39236111 | G22: 50 | H22: HANSEN | I22: 6.62 | J22: 33.5 | K22: 403 | L22: 0.40138889 | M22: 0.41944444 | O22: 6.57 | P22: 36.3 | Q22: 0.44236111 | R22: 40.3 | S22: 6.51 | T22: 0.47291667 | V22: 0.56944444 | W22: 5.56 | X22: 41.3 | Y22: 28.25 | Z22: 25.4 | AA22: 25.3 | AB22: 26.7 | AC22: 25.1 | AD22: 23.7 | AE22: 23.7 | AF22: 23.1 | AG22: 25.5 | AH22: 27 | AI22: 25.8 | AJ22: 26.6 | AK22: 25.25 | AL22: 22 | BQ22: =SUM(Y22:BP22) -> 353.4 | BR22: =C22/BQ22 -> 7.3571024
A23: 46050 | B23: 280126 | C23: 2600 | E23: 0.45833333 | F23: 0.48055556 | G23: 50 | H23: HANSEN | I23: 6.67 | J23: 34.3 | L23: 0.48958333 | M23: 0.51041667 | N23: 39.5 | O23: 6.6 | P23: 36.4 | Q23: 0.53819444 | R23: 41.4 | S23: 6.57 | T23: 0.52777778 | U23: 0.59027778 | W23: 5.68 | X23: 42.6 | Y23: 23.25 | Z23: 24.75 | AA23: 23.95 | AB23: 25.4 | AC23: 24.6 | AD23: 21.9 | AE23: 24.2 | AF23: 26 | AG23: 25.95 | AH23: 25.6 | AI23: 23.8 | AJ23: 22.95 | AK23: 26.7 | AL23: 24.75 | BQ23: =SUM(Y23:BP23) -> 343.8 | BR23: =C23/BQ23 -> 7.5625364
A24: 46051 | B24: 290126 | C24: 2400 | E24: 0.36111111 | F24: 0.42361111 | G24: 75 | H24: HANSEN | I24: 6.72 | J24: 33.01 | K24: 180 | L24: 0.43958333 | M24: 0.45138889 | N24: 64 | O24: 6.68 | P24: 35.5 | Q24: 0.48055556 | R24: 40.5 | S24: 6.58 | T24: 0.50555556 | V24: 0.76041667 | W24: 6.47 | X24: 30 | Y24: 376.85 | BQ24: =SUM(Y24:BP24) -> 376.85 | BR24: =C24/BQ24 -> 6.3685817
A25: 46052 | B25: 300126 | C25: 2150 | E25: 0.35 | F25: 0.43888889 | G25: 50 | H25: HANSEN | I25: 7.64 | J25: 32.22 | L25: 0.40902778 | M25: 0.41736111 | N25: 35 | O25: 7.57 | P25: 36.5 | Q25: 0.44930556 | R25: 40.7 | S25: 7.5 | T25: 0.44097222 | U25: 0.47222222 | V25: 0.57083333 | W25: 6.77 | X25: 42.1 | Y25: 24.15 | Z25: 20.665 | AA25: 17.85 | AB25: 22.65 | AC25: 20.6 | AD25: 18.1 | AE25: 23.55 | AF25: 23.7 | AG25: 24.3 | AH25: 24.55 | AI25: 25.6 | AJ25: 6.85 | AK25: 6.45 | AL25: 7.05 | AM25: 3.85 | AN25: 6.65 | BQ25: =SUM(Y25:BP25) -> 276.565 | BR25: =C25/BQ25 -> 7.773941
A26: 46053 | B26: 310126 | C26: 2500 | E26: 0.31805556 | F26: 0.37291667 | G26: 50 | H26: HANSEN | I26: 6.63 | J26: 31 | K26: 440 | L26: 0.37430556 | M26: 0.38541667 | N26: 38.5 | O26: 6.46 | P26: 36.6 | Q26: 0.41388889 | R26: 41.4 | S26: 6.4 | T26: 0.45138889 | U26: 0.47569444 | V26: 0.5 | W26: 5.78 | X26: 41.2 | Y26: 26.5 | Z26: 27.35 | AA26: 26 | AB26: 24.35 | AC26: 22.6 | AD26: 14.7 | AE26: 22.05 | AF26: 30.8 | AG26: 25.5 | AH26: 20.85 | AI26: 27.95 | AJ26: 25.36 | AK26: 24.75 | AL26: 23.65 | BQ26: =SUM(Y26:BP26) -> 342.41 | BR26: =C26/BQ26 -> 7.3011886
A27: 46056 | B27: 30226 | C27: 2600 | E27: 0.41111111 | F27: 0.44583333 | G27: 50 | H27: HANSEN | I27: 6.46 | J27: 30 | K27: 520.5 | L27: 0.46111111 | M27: 0.47708333 | N27: 41 | O27: 5.69 | P27: 36.6 | Q27: 0.50555556 | R27: 40.8 | S27: 5.17 | T27: 0.53611111 | U27: 0.5625 | V27: 0.60763889 | X27: 41.7 | Y27: 28.6 | Z27: 25.1 | AA27: 26.75 | AB27: 23.9 | AC27: 22.45 | AD27: 26.75 | AE27: 23.9 | AF27: 21.95 | AG27: 26.3 | AH27: 23.9 | AI27: 25.55 | AJ27: 21.85 | AK27: 22.5 | AL27: 25.8 | BQ27: =SUM(Y27:BP27) -> 345.3 | BR27: =C27/BQ27 -> 7.5296843
A28: 46057 | B28: 40226 | C28: 2500 | F28: 0.34513889 | G28: 50 | H28: HANSEN | J28: 33.2 | K28: 500 | L28: 0.38125 | M28: 0.40486111 | N28: 41.5 | P28: 36.6 | Q28: 0.43263889 | R28: 36.4 | T28: 0.46666667 | U28: 0.51388889 | V28: 0.58333333 | X28: 40.2 | Y28: 74.35 | Z28: 75.55 | AA28: 48 | AB28: 45.55 | AC28: 48.1 | BQ28: =SUM(Y28:BP28) -> 291.55 | BR28: =C28/BQ28 -> 8.5748585
